Workbook

Sheet Pregled
A1: Zona 2, 2026: pregled odvoza
A3: Danas | B3: =TODAY()
A5: Vrsta otpada | B5: Sljedeći odvoz | C5: Dan | D5: Za dana | E5: Ukupno u 2026.
A6: Miješani komunalni otpad | B6: =IFERROR(1/(1/_xlfn.MINIFS(Raspored!$A$5:$A$170,Raspored!$D$5:$D$170,"x",Raspored!$A$5:$A$170,">="&$B$3)),"nema više u 2026.") | C6: =IF(ISNUMBER(B6),INDEX({"nedjelja","ponedjeljak","utorak","srijeda","četvrtak","petak","subota"},WEEKDAY(B6)),"") | D6: =IF(ISNUMBER(B6),B6-$B$3,"") | E6: =COUNTIF(Raspored!$D$5:$D$170,"x")
A7: Biootpad | B7: =IFERROR(1/(1/_xlfn.MINIFS(Raspored!$A$5:$A$170,Raspored!$E$5:$E$170,"x",Raspored!$A$5:$A$170,">="&$B$3)),"nema više u 2026.") | C7: =IF(ISNUMBER(B7),INDEX({"nedjelja","ponedjeljak","utorak","srijeda","četvrtak","petak","subota"},WEEKDAY(B7)),"") | D7: =IF(ISNUMBER(B7),B7-$B$3,"") | E7: =COUNTIF(Raspored!$E$5:$E$170,"x")
A8: Plastika i metal | B8: =IFERROR(1/(1/_xlfn.MINIFS(Raspored!$A$5:$A$170,Raspored!$F$5:$F$170,"x",Raspored!$A$5:$A$170,">="&$B$3)),"nema više u 2026.") | C8: =IF(ISNUMBER(B8),INDEX({"nedjelja","ponedjeljak","utorak","srijeda","četvrtak","petak","subota"},WEEKDAY(B8)),"") | D8: =IF(ISNUMBER(B8),B8-$B$3,"") | E8: =COUNTIF(Raspored!$F$5:$F$170,"x")
A9: Papir i karton | B9: =IFERROR(1/(1/_xlfn.MINIFS(Raspored!$A$5:$A$170,Raspored!$G$5:$G$170,"x",Raspored!$A$5:$A$170,">="&$B$3)),"nema više u 2026.") | C9: =IF(ISNUMBER(B9),INDEX({"nedjelja","ponedjeljak","utorak","srijeda","četvrtak","petak","subota"},WEEKDAY(B9)),"") | D9: =IF(ISNUMBER(B9),B9-$B$3,"") | E9: =COUNTIF(Raspored!$G$5:$G$170,"x")
A10: Staklo | B10: =IFERROR(1/(1/_xlfn.MINIFS(Raspored!$A$5:$A$170,Raspored!$H$5:$H$170,"x",Raspored!$A$5:$A$170,">="&$B$3)),"nema više u 2026.") | C10: =IF(ISNUMBER(B10),INDEX({"nedjelja","ponedjeljak","utorak","srijeda","četvrtak","petak","subota"},WEEKDAY(B10)),"") | D10: =IF(ISNUMBER(B10),B10-$B$3,"") | E10: =COUNTIF(Raspored!$H$5:$H$170,"x")
A11: Metal (zajedno sa staklom) | B11: =IFERROR(1/(1/_xlfn.MINIFS(Raspored!$A$5:$A$170,Raspored!$I$5:$I$170,"x",Raspored!$A$5:$A$170,">="&$B$3)),"nema više u 2026.") | C11: =IF(ISNUMBER(B11),INDEX({"nedjelja","ponedjeljak","utorak","srijeda","četvrtak","petak","subota"},WEEKDAY(B11)),"") | D11: =IF(ISNUMBER(B11),B11-$B$3,"") | E11: =COUNTIF(Raspored!$I$5:$I$170,"x")
A12: Glomazni i EE otpad (na zahtjev) | B12: =IFERROR(1/(1/_xlfn.MINIFS(Raspored!$A$5:$A$170,Raspored!$J$5:$J$170,"x",Raspored!$A$5:$A$170,">="&$B$3)),"nema više u 2026.") | C12: =IF(ISNUMBER(B12),INDEX({"nedjelja","ponedjeljak","utorak","srijeda","četvrtak","petak","subota"},WEEKDAY(B12)),"") | D12: =IF(ISNUMBER(B12),B12-$B$3,"") | E12: =COUNTIF(Raspored!$J$5:$J$170,"x")
A14: Broj odvoza po mjesecu
A15: Mjesec | B15: Miješani komunalni otpad | C15: Biootpad | D15: Plastika i metal | E15: Papir i karton | F15: Staklo | G15: Metal (zajedno sa staklom) | H15: Glomazni i EE otpad (na zahtjev)
A16: siječanj | B16: =COUNTIFS(Raspored!$C$5:$C$170,$A16,Raspored!$D$5:$D$170,"x") | C16: =COUNTIFS(Raspored!$C$5:$C$170,$A16,Raspored!$E$5:$E$170,"x") | D16: =COUNTIFS(Raspored!$C$5:$C$170,$A16,Raspored!$F$5:$F$170,"x") | E16: =COUNTIFS(Raspored!$C$5:$C$170,$A16,Raspored!$G$5:$G$170,"x") | F16: =COUNTIFS(Raspored!$C$5:$C$170,$A16,Raspored!$H$5:$H$170,"x") | G16: =COUNTIFS(Raspored!$C$5:$C$170,$A16,Raspored!$I$5:$I$170,"x") | H16: =COUNTIFS(Raspored!$C$5:$C$170,$A16,Raspored!$J$5:$J$170,"x")
A17: veljača | B17: =COUNTIFS(Raspored!$C$5:$C$170,$A17,Raspored!$D$5:$D$170,"x") | C17: =COUNTIFS(Raspored!$C$5:$C$170,$A17,Raspored!$E$5:$E$170,"x") | D17: =COUNTIFS(Raspored!$C$5:$C$170,$A17,Raspored!$F$5:$F$170,"x") | E17: =COUNTIFS(Raspored!$C$5:$C$170,$A17,Raspored!$G$5:$G$170,"x") | F17: =COUNTIFS(Raspored!$C$5:$C$170,$A17,Raspored!$H$5:$H$170,"x") | G17: =COUNTIFS(Raspored!$C$5:$C$170,$A17,Raspored!$I$5:$I$170,"x") | H17: =COUNTIFS(Raspored!$C$5:$C$170,$A17,Raspored!$J$5:$J$170,"x")
A18: ožujak | B18: =COUNTIFS(Raspored!$C$5:$C$170,$A18,Raspored!$D$5:$D$170,"x") | C18: =COUNTIFS(Raspored!$C$5:$C$170,$A18,Raspored!$E$5:$E$170,"x") | D18: =COUNTIFS(Raspored!$C$5:$C$170,$A18,Raspored!$F$5:$F$170,"x") | E18: =COUNTIFS(Raspored!$C$5:$C$170,$A18,Raspored!$G$5:$G$170,"x") | F18: =COUNTIFS(Raspored!$C$5:$C$170,$A18,Raspored!$H$5:$H$170,"x") | G18: =COUNTIFS(Raspored!$C$5:$C$170,$A18,Raspored!$I$5:$I$170,"x") | H18: =COUNTIFS(Raspored!$C$5:$C$170,$A18,Raspored!$J$5:$J$170,"x")
A19: travanj | B19: =COUNTIFS(Raspored!$C$5:$C$170,$A19,Raspored!$D$5:$D$170,"x") | C19: =COUNTIFS(Raspored!$C$5:$C$170,$A19,Raspored!$E$5:$E$170,"x") | D19: =COUNTIFS(Raspored!$C$5:$C$170,$A19,Raspored!$F$5:$F$170,"x") | E19: =COUNTIFS(Raspored!$C$5:$C$170,$A19,Raspored!$G$5:$G$170,"x") | F19: =COUNTIFS(Raspored!$C$5:$C$170,$A19,Raspored!$H$5:$H$170,"x") | G19: =COUNTIFS(Raspored!$C$5:$C$170,$A19,Raspored!$I$5:$I$170,"x") | H19: =COUNTIFS(Raspored!$C$5:$C$170,$A19,Raspored!$J$5:$J$170,"x")
A20: svibanj | B20: =COUNTIFS(Raspored!$C$5:$C$170,$A20,Raspored!$D$5:$D$170,"x") | C20: =COUNTIFS(Raspored!$C$5:$C$170,$A20,Raspored!$E$5:$E$170,"x") | D20: =COUNTIFS(Raspored!$C$5:$C$170,$A20,Raspored!$F$5:$F$170,"x") | E20: =COUNTIFS(Raspored!$C$5:$C$170,$A20,Raspored!$G$5:$G$170,"x") | F20: =COUNTIFS(Raspored!$C$5:$C$170,$A20,Raspored!$H$5:$H$170,"x") | G20: =COUNTIFS(Raspored!$C$5:$C$170,$A20,Raspored!$I$5:$I$170,"x") | H20: =COUNTIFS(Raspored!$C$5:$C$170,$A20,Raspored!$J$5:$J$170,"x")
A21: lipanj | B21: =COUNTIFS(Raspored!$C$5:$C$170,$A21,Raspored!$D$5:$D$170,"x") | C21: =COUNTIFS(Raspored!$C$5:$C$170,$A21,Raspored!$E$5:$E$170,"x") | D21: =COUNTIFS(Raspored!$C$5:$C$170,$A21,Raspored!$F$5:$F$170,"x") | E21: =COUNTIFS(Raspored!$C$5:$C$170,$A21,Raspored!$G$5:$G$170,"x") | F21: =COUNTIFS(Raspored!$C$5:$C$170,$A21,Raspored!$H$5:$H$170,"x") | G21: =COUNTIFS(Raspored!$C$5:$C$170,$A21,Raspored!$I$5:$I$170,"x") | H21: =COUNTIFS(Raspored!$C$5:$C$170,$A21,Raspored!$J$5:$J$170,"x")
A22: srpanj | B22: =COUNTIFS(Raspored!$C$5:$C$170,$A22,Raspored!$D$5:$D$170,"x") | C22: =COUNTIFS(Raspored!$C$5:$C$170,$A22,Raspored!$E$5:$E$170,"x") | D22: =COUNTIFS(Raspored!$C$5:$C$170,$A22,Raspored!$F$5:$F$170,"x") | E22: =COUNTIFS(Raspored!$C$5:$C$170,$A22,Raspored!$G$5:$G$170,"x") | F22: =COUNTIFS(Raspored!$C$5:$C$170,$A22,Raspored!$H$5:$H$170,"x") | G22: =COUNTIFS(Raspored!$C$5:$C$170,$A22,Raspored!$I$5:$I$170,"x") | H22: =COUNTIFS(Raspored!$C$5:$C$170,$A22,Raspored!$J$5:$J$170,"x")
A23: kolovoz | B23: =COUNTIFS(Raspored!$C$5:$C$170,$A23,Raspored!$D$5:$D$170,"x") | C23: =COUNTIFS(Raspored!$C$5:$C$170,$A23,Raspored!$E$5:$E$170,"x") | D23: =COUNTIFS(Raspored!$C$5:$C$170,$A23,Raspored!$F$5:$F$170,"x") | E23: =COUNTIFS(Raspored!$C$5:$C$170,$A23,Raspored!$G$5:$G$170,"x") | F23: =COUNTIFS(Raspored!$C$5:$C$170,$A23,Raspored!$H$5:$H$170,"x") | G23: =COUNTIFS(Raspored!$C$5:$C$170,$A23,Raspored!$I$5:$I$170,"x") | H23: =COUNTIFS(Raspored!$C$5:$C$170,$A23,Raspored!$J$5:$J$170,"x")
A24: rujan | B24: =COUNTIFS(Raspored!$C$5:$C$170,$A24,Raspored!$D$5:$D$170,"x") | C24: =COUNTIFS(Raspored!$C$5:$C$170,$A24,Raspored!$E$5:$E$170,"x") | D24: =COUNTIFS(Raspored!$C$5:$C$170,$A24,Raspored!$F$5:$F$170,"x") | E24: =COUNTIFS(Raspored!$C$5:$C$170,$A24,Raspored!$G$5:$G$170,"x") | F24: =COUNTIFS(Raspored!$C$5:$C$170,$A24,Raspored!$H$5:$H$170,"x") | G24: =COUNTIFS(Raspored!$C$5:$C$170,$A24,Raspored!$I$5:$I$170,"x") | H24: =COUNTIFS(Raspored!$C$5:$C$170,$A24,Raspored!$J$5:$J$170,"x")
A25: listopad | B25: =COUNTIFS(Raspored!$C$5:$C$170,$A25,Raspored!$D$5:$D$170,"x") | C25: =COUNTIFS(Raspored!$C$5:$C$170,$A25,Raspored!$E$5:$E$170,"x") | D25: =COUNTIFS(Raspored!$C$5:$C$170,$A25,Raspored!$F$5:$F$170,"x") | E25: =COUNTIFS(Raspored!$C$5:$C$170,$A25,Raspored!$G$5:$G$170,"x") | F25: =COUNTIFS(Raspored!$C$5:$C$170,$A25,Raspored!$H$5:$H$170,"x") | G25: =COUNTIFS(Raspored!$C$5:$C$170,$A25,Raspored!$I$5:$I$170,"x") | H25: =COUNTIFS(Raspored!$C$5:$C$170,$A25,Raspored!$J$5:$J$170,"x")
A26: studeni | B26: =COUNTIFS(Raspored!$C$5:$C$170,$A26,Raspored!$D$5:$D$170,"x") | C26: =COUNTIFS(Raspored!$C$5:$C$170,$A26,Raspored!$E$5:$E$170,"x") | D26: =COUNTIFS(Raspored!$C$5:$C$170,$A26,Raspored!$F$5:$F$170,"x") | E26: =COUNTIFS(Raspored!$C$5:$C$170,$A26,Raspored!$G$5:$G$170,"x") | F26: =COUNTIFS(Raspored!$C$5:$C$170,$A26,Raspored!$H$5:$H$170,"x") | G26: =COUNTIFS(Raspored!$C$5:$C$170,$A26,Raspored!$I$5:$I$170,"x") | H26: =COUNTIFS(Raspored!$C$5:$C$170,$A26,Raspored!$J$5:$J$170,"x")
A27: prosinac | B27: =COUNTIFS(Raspored!$C$5:$C$170,$A27,Raspored!$D$5:$D$170,"x") | C27: =COUNTIFS(Raspored!$C$5:$C$170,$A27,Raspored!$E$5:$E$170,"x") | D27: =COUNTIFS(Raspored!$C$5:$C$170,$A27,Raspored!$F$5:$F$170,"x") | E27: =COUNTIFS(Raspored!$C$5:$C$170,$A27,Raspored!$G$5:$G$170,"x") | F27: =COUNTIFS(Raspored!$C$5:$C$170,$A27,Raspored!$H$5:$H$170,"x") | G27: =COUNTIFS(Raspored!$C$5:$C$170,$A27,Raspored!$I$5:$I$170,"x") | H27: =COUNTIFS(Raspored!$C$5:$C$170,$A27,Raspored!$J$5:$J$170,"x")
A28: Ukupno | B28: =SUM(B16:B27) | C28: =SUM(C16:C27) | D28: =SUM(D16:D27) | E28: =SUM(E16:E27) | F28: =SUM(F16:F27) | G28: =SUM(G16:G27) | H28: =SUM(H16:H27)
A30: Napomene:
A31: • Za 2026. objavljeni su mjeseci: 1., 2., 3., 4., 5., 6., 7., 8., 9., 10. (raspored izlazi mjesec po mjesec).
A32: • Raspored se objavljuje mjesečno ili za dva mjeseca; ljeti (lipanj-kolovoz) zaseban raspored za Kolan, Mandre i Kolanjski Gajac, inače zajednički.
A33: • Metal i staklo odvoze se zajedno ("METAL / STAKLO").
A34: • Glomazni otpad i EE otpad odvoze se na označene dane samo uz zahtjev (obrazac na ciok.hr).
A35: • Na blagdane označene u rasporedu nema odvoza; pomaci su već upisani u datume.
A36: • Kontakt: 023/698-017, info@ciok.hr (radnim danom 07:00-15:00).

Sheet Raspored
A1: Raspored odvoza otpada 2026., Zona 2 (Kolan)
A2: "x" = odvoz tog dana. Spremnike iznijeti do 07:00. Prošli datumi su posivljeni.
A4: Datum | B4: Dan | C4: Mjesec | D4: Miješani komunalni otpad | E4: Biootpad | F4: Plastika i metal | G4: Papir i karton | H4: Staklo | I4: Metal (zajedno sa staklom) | J4: Glomazni i EE otpad (na zahtjev) | K4: Napomena
A5: 46027 | B5: ponedjeljak | C5: siječanj | D5: x | E5: x
A6: 46034 | B6: ponedjeljak | C6: siječanj | D6: x
A7: 46035 | B7: utorak | C7: siječanj | F7: x
A8: 46036 | B8: srijeda | C8: siječanj | G8: x
A9: 46038 | B9: petak | C9: siječanj | H9: x | I9: x
A10: 46041 | B10: ponedjeljak | C10: siječanj | D10: x | E10: x
A11: 46045 | B11: petak | C11: siječanj | J11: x
A12: 46048 | B12: ponedjeljak | C12: siječanj | D12: x
A13: 46055 | B13: ponedjeljak | C13: veljača | D13: x | E13: x
A14: 46062 | B14: ponedjeljak | C14: veljača | D14: x
A15: 46063 | B15: utorak | C15: veljača | F15: x
A16: 46064 | B16: srijeda | C16: veljača | G16: x
A17: 46066 | B17: petak | C17: veljača | H17: x | I17: x
A18: 46069 | B18: ponedjeljak | C18: veljača | D18: x | E18: x
A19: 46076 | B19: ponedjeljak | C19: veljača | D19: x
A20: 46083 | B20: ponedjeljak | C20: ožujak | D20: x | E20: x
A21: 46090 | B21: ponedjeljak | C21: ožujak | D21: x
A22: 46091 | B22: utorak | C22: ožujak | F22: x
A23: 46092 | B23: srijeda | C23: ožujak | G23: x
A24: 46094 | B24: petak | C24: ožujak | H24: x | I24: x
A25: 46097 | B25: ponedjeljak | C25: ožujak | D25: x | E25: x
A26: 46104 | B26: ponedjeljak | C26: ožujak | D26: x
A27: 46111 | B27: ponedjeljak | C27: ožujak | D27: x | E27: x
A28: 46119 | B28: utorak | C28: travanj | D28: x | E28: x
A29: 46122 | B29: petak | C29: travanj | D29: x
A30: 46125 | B30: ponedjeljak | C30: travanj | D30: x
A31: 46126 | B31: utorak | C31: travanj | F31: x
A32: 46127 | B32: srijeda | C32: travanj | G32: x
A33: 46129 | B33: petak | C33: travanj | H33: x | I33: x
A34: 46132 | B34: ponedjeljak | C34: travanj | D34: x | E34: x
A35: 46135 | B35: četvrtak | C35: travanj | D35: x
A36: 46139 | B36: ponedjeljak | C36: travanj | D36: x | J36: x
A37: 46140 | B37: utorak | C37: travanj | J37: x
A38: 46141 | B38: srijeda | C38: travanj | J38: x
A39: 46142 | B39: četvrtak | C39: travanj | J39: x
A40: 46146 | B40: ponedjeljak | C40: svibanj | D40: x | J40: x
A41: 46147 | B41: utorak | C41: svibanj | J41: x
...

Sheet Po vrsti
A1: Datum | B1: Dan | C1: Vrsta otpada | D1: Napomena
A2: 46027 | B2: ponedjeljak | C2: Miješani komunalni otpad
A3: 46027 | B3: ponedjeljak | C3: Biootpad
A4: 46034 | B4: ponedjeljak | C4: Miješani komunalni otpad
A5: 46035 | B5: utorak | C5: Plastika i metal
A6: 46036 | B6: srijeda | C6: Papir i karton
A7: 46038 | B7: petak | C7: Staklo
A8: 46038 | B8: petak | C8: Metal (zajedno sa staklom)
A9: 46041 | B9: ponedjeljak | C9: Miješani komunalni otpad
A10: 46041 | B10: ponedjeljak | C10: Biootpad
A11: 46045 | B11: petak | C11: Glomazni i EE otpad (na zahtjev)
A12: 46048 | B12: ponedjeljak | C12: Miješani komunalni otpad
A13: 46055 | B13: ponedjeljak | C13: Miješani komunalni otpad
... A224: 46324 | B224: četvrtak | C224: Biootpad

Sheet Ulice i naselja
A1: Zona 2 (Kolan): ulice i naselja
A4: Ulica / naselje
A5: Mandre
