Workbook

Sheet Pregled
A1: Zona 10, 2026: pregled odvoza
A3: Danas | B3: =TODAY()
A5: Vrsta otpada | B5: Sljedeći odvoz | C5: Dan | D5: Za dana | E5: Ukupno u 2026.
A6: Miješani komunalni otpad | B6: =IFERROR(1/(1/_xlfn.MINIFS(Raspored!$A$5:$A$55,Raspored!$D$5:$D$55,"x",Raspored!$A$5:$A$55,">="&$B$3)),"nema više u 2026.") | C6: =IF(ISNUMBER(B6),INDEX({"nedjelja","ponedjeljak","utorak","srijeda","četvrtak","petak","subota"},WEEKDAY(B6)),"") | D6: =IF(ISNUMBER(B6),B6-$B$3,"") | E6: =COUNTIF(Raspored!$D$5:$D$55,"x")
A7: Plastika (vreća) | B7: =IFERROR(1/(1/_xlfn.MINIFS(Raspored!$A$5:$A$55,Raspored!$E$5:$E$55,"x",Raspored!$A$5:$A$55,">="&$B$3)),"nema više u 2026.") | C7: =IF(ISNUMBER(B7),INDEX({"nedjelja","ponedjeljak","utorak","srijeda","četvrtak","petak","subota"},WEEKDAY(B7)),"") | D7: =IF(ISNUMBER(B7),B7-$B$3,"") | E7: =COUNTIF(Raspored!$E$5:$E$55,"x")
A8: Papir (vreća) | B8: =IFERROR(1/(1/_xlfn.MINIFS(Raspored!$A$5:$A$55,Raspored!$F$5:$F$55,"x",Raspored!$A$5:$A$55,">="&$B$3)),"nema više u 2026.") | C8: =IF(ISNUMBER(B8),INDEX({"nedjelja","ponedjeljak","utorak","srijeda","četvrtak","petak","subota"},WEEKDAY(B8)),"") | D8: =IF(ISNUMBER(B8),B8-$B$3,"") | E8: =COUNTIF(Raspored!$F$5:$F$55,"x")
A9: Glomazni otpad | B9: =IFERROR(1/(1/_xlfn.MINIFS(Raspored!$A$5:$A$55,Raspored!$G$5:$G$55,"x",Raspored!$A$5:$A$55,">="&$B$3)),"nema više u 2026.") | C9: =IF(ISNUMBER(B9),INDEX({"nedjelja","ponedjeljak","utorak","srijeda","četvrtak","petak","subota"},WEEKDAY(B9)),"") | D9: =IF(ISNUMBER(B9),B9-$B$3,"") | E9: =COUNTIF(Raspored!$G$5:$G$55,"x")
A11: Broj odvoza po mjesecu
A12: Mjesec | B12: Miješani komunalni otpad | C12: Plastika (vreća) | D12: Papir (vreća) | E12: Glomazni otpad
A13: siječanj | B13: =COUNTIFS(Raspored!$C$5:$C$55,$A13,Raspored!$D$5:$D$55,"x") | C13: =COUNTIFS(Raspored!$C$5:$C$55,$A13,Raspored!$E$5:$E$55,"x") | D13: =COUNTIFS(Raspored!$C$5:$C$55,$A13,Raspored!$F$5:$F$55,"x") | E13: =COUNTIFS(Raspored!$C$5:$C$55,$A13,Raspored!$G$5:$G$55,"x")
A14: veljača | B14: =COUNTIFS(Raspored!$C$5:$C$55,$A14,Raspored!$D$5:$D$55,"x") | C14: =COUNTIFS(Raspored!$C$5:$C$55,$A14,Raspored!$E$5:$E$55,"x") | D14: =COUNTIFS(Raspored!$C$5:$C$55,$A14,Raspored!$F$5:$F$55,"x") | E14: =COUNTIFS(Raspored!$C$5:$C$55,$A14,Raspored!$G$5:$G$55,"x")
A15: ožujak | B15: =COUNTIFS(Raspored!$C$5:$C$55,$A15,Raspored!$D$5:$D$55,"x") | C15: =COUNTIFS(Raspored!$C$5:$C$55,$A15,Raspored!$E$5:$E$55,"x") | D15: =COUNTIFS(Raspored!$C$5:$C$55,$A15,Raspored!$F$5:$F$55,"x") | E15: =COUNTIFS(Raspored!$C$5:$C$55,$A15,Raspored!$G$5:$G$55,"x")
A16: travanj | B16: =COUNTIFS(Raspored!$C$5:$C$55,$A16,Raspored!$D$5:$D$55,"x") | C16: =COUNTIFS(Raspored!$C$5:$C$55,$A16,Raspored!$E$5:$E$55,"x") | D16: =COUNTIFS(Raspored!$C$5:$C$55,$A16,Raspored!$F$5:$F$55,"x") | E16: =COUNTIFS(Raspored!$C$5:$C$55,$A16,Raspored!$G$5:$G$55,"x")
A17: svibanj | B17: =COUNTIFS(Raspored!$C$5:$C$55,$A17,Raspored!$D$5:$D$55,"x") | C17: =COUNTIFS(Raspored!$C$5:$C$55,$A17,Raspored!$E$5:$E$55,"x") | D17: =COUNTIFS(Raspored!$C$5:$C$55,$A17,Raspored!$F$5:$F$55,"x") | E17: =COUNTIFS(Raspored!$C$5:$C$55,$A17,Raspored!$G$5:$G$55,"x")
A18: lipanj | B18: =COUNTIFS(Raspored!$C$5:$C$55,$A18,Raspored!$D$5:$D$55,"x") | C18: =COUNTIFS(Raspored!$C$5:$C$55,$A18,Raspored!$E$5:$E$55,"x") | D18: =COUNTIFS(Raspored!$C$5:$C$55,$A18,Raspored!$F$5:$F$55,"x") | E18: =COUNTIFS(Raspored!$C$5:$C$55,$A18,Raspored!$G$5:$G$55,"x")
A19: srpanj | B19: =COUNTIFS(Raspored!$C$5:$C$55,$A19,Raspored!$D$5:$D$55,"x") | C19: =COUNTIFS(Raspored!$C$5:$C$55,$A19,Raspored!$E$5:$E$55,"x") | D19: =COUNTIFS(Raspored!$C$5:$C$55,$A19,Raspored!$F$5:$F$55,"x") | E19: =COUNTIFS(Raspored!$C$5:$C$55,$A19,Raspored!$G$5:$G$55,"x")
A20: kolovoz | B20: =COUNTIFS(Raspored!$C$5:$C$55,$A20,Raspored!$D$5:$D$55,"x") | C20: =COUNTIFS(Raspored!$C$5:$C$55,$A20,Raspored!$E$5:$E$55,"x") | D20: =COUNTIFS(Raspored!$C$5:$C$55,$A20,Raspored!$F$5:$F$55,"x") | E20: =COUNTIFS(Raspored!$C$5:$C$55,$A20,Raspored!$G$5:$G$55,"x")
A21: rujan | B21: =COUNTIFS(Raspored!$C$5:$C$55,$A21,Raspored!$D$5:$D$55,"x") | C21: =COUNTIFS(Raspored!$C$5:$C$55,$A21,Raspored!$E$5:$E$55,"x") | D21: =COUNTIFS(Raspored!$C$5:$C$55,$A21,Raspored!$F$5:$F$55,"x") | E21: =COUNTIFS(Raspored!$C$5:$C$55,$A21,Raspored!$G$5:$G$55,"x")
A22: listopad | B22: =COUNTIFS(Raspored!$C$5:$C$55,$A22,Raspored!$D$5:$D$55,"x") | C22: =COUNTIFS(Raspored!$C$5:$C$55,$A22,Raspored!$E$5:$E$55,"x") | D22: =COUNTIFS(Raspored!$C$5:$C$55,$A22,Raspored!$F$5:$F$55,"x") | E22: =COUNTIFS(Raspored!$C$5:$C$55,$A22,Raspored!$G$5:$G$55,"x")
A23: studeni | B23: =COUNTIFS(Raspored!$C$5:$C$55,$A23,Raspored!$D$5:$D$55,"x") | C23: =COUNTIFS(Raspored!$C$5:$C$55,$A23,Raspored!$E$5:$E$55,"x") | D23: =COUNTIFS(Raspored!$C$5:$C$55,$A23,Raspored!$F$5:$F$55,"x") | E23: =COUNTIFS(Raspored!$C$5:$C$55,$A23,Raspored!$G$5:$G$55,"x")
A24: prosinac | B24: =COUNTIFS(Raspored!$C$5:$C$55,$A24,Raspored!$D$5:$D$55,"x") | C24: =COUNTIFS(Raspored!$C$5:$C$55,$A24,Raspored!$E$5:$E$55,"x") | D24: =COUNTIFS(Raspored!$C$5:$C$55,$A24,Raspored!$F$5:$F$55,"x") | E24: =COUNTIFS(Raspored!$C$5:$C$55,$A24,Raspored!$G$5:$G$55,"x")
A25: Ukupno | B25: =SUM(B13:B24) | C25: =SUM(C13:C24) | D25: =SUM(D13:D24) | E25: =SUM(E13:E24)
A27: Napomene:
A28: • Crveno označeni datumi u listu "Raspored" su pomaknuti zbog neradnog dana u tom tjednu (inače je odvoz utorkom).
A29: • U stupcu za ožujak upisan je i datum 31.04. (ne postoji; vjerojatno 31.03.), pa nije upisan – provjerite kod davatelja.
A30: • Kalendar odvoza 2026. objavljen je po skupinama naselja (skenirani PDF-ovi). Datumi ispisani crvenom bojom su promijenjeni dani odvoza zbog blagdana ili praznika i označeni su kao pomaknuti.
A31: • Papir i plastika predaju se u plastičnim vrećama koje moraju biti vezane i stavljene na prilaz kući.
A32: • Glomazni otpad: jednom godišnje prema kalendaru, besplatno do 5 m³ (u Lasinji do 3 m³); veće količine naplaćuju se prema cjeniku.
A33: • Općina Lasinja: Registar (IRDJU 2024) još navodi EKO-FLOR PLUS d.o.o., ali Vojnić komunalac objavljuje kalendar za 2026. i Ugovor o obavljanju javne usluge za Lasinju (ožujak 2026.).
A34: • Neki datumi u skenovima nisu mogući (nedjelja, 31.04., utorak umjesto srijede) i nisu upisani; vidi napomenu zone.
A35: • Vojnić komunalac d.o.o., Andrije Hebranga 9, 47220 Vojnić.

Sheet Raspored
A1: Raspored odvoza otpada 2026., Zona 10 (Cetingrad)
A2: "x" = odvoz tog dana. Spremnike iznijeti do 07:00. Prošli datumi su posivljeni.
A4: Datum | B4: Dan | C4: Mjesec | D4: Miješani komunalni otpad | E4: Plastika (vreća) | F4: Papir (vreća) | G4: Glomazni otpad | H4: Napomena
A5: 46029 | B5: srijeda | C5: siječanj | D5: x | H5: Pomaknuto zbog neradnog dana u tjednu
A6: 46035 | B6: utorak | C6: siječanj | D6: x
A7: 46042 | B7: utorak | C7: siječanj | D7: x | E7: x | F7: x
A8: 46049 | B8: utorak | C8: siječanj | D8: x
A9: 46056 | B9: utorak | C9: veljača | D9: x
A10: 46063 | B10: utorak | C10: veljača | D10: x
A11: 46070 | B11: utorak | C11: veljača | D11: x | E11: x | F11: x
A12: 46077 | B12: utorak | C12: veljača | D12: x
A13: 46084 | B13: utorak | C13: ožujak | D13: x
A14: 46091 | B14: utorak | C14: ožujak | D14: x
A15: 46098 | B15: utorak | C15: ožujak | D15: x | E15: x | F15: x
A16: 46105 | B16: utorak | C16: ožujak | D16: x
A17: 46120 | B17: srijeda | C17: travanj | D17: x | H17: Pomaknuto zbog neradnog dana u tjednu
A18: 46126 | B18: utorak | C18: travanj | D18: x | E18: x | F18: x
A19: 46133 | B19: utorak | C19: travanj | D19: x
A20: 46140 | B20: utorak | C20: travanj | D20: x
A21: 46147 | B21: utorak | C21: svibanj | D21: x
A22: 46154 | B22: utorak | C22: svibanj | D22: x | E22: x | F22: x
A23: 46161 | B23: utorak | C23: svibanj | D23: x
A24: 46168 | B24: utorak | C24: svibanj | D24: x
A25: 46175 | B25: utorak | C25: lipanj | D25: x
A26: 46182 | B26: utorak | C26: lipanj | D26: x
A27: 46189 | B27: utorak | C27: lipanj | D27: x
A28: 46197 | B28: srijeda | C28: lipanj | D28: x | E28: x | F28: x | H28: Pomaknuto zbog neradnog dana u tjednu
A29: 46203 | B29: utorak | C29: lipanj | D29: x
A30: 46210 | B30: utorak | C30: srpanj | D30: x
A31: 46217 | B31: utorak | C31: srpanj | D31: x
A32: 46224 | B32: utorak | C32: srpanj | D32: x | E32: x | F32: x | G32: x
A33: 46231 | B33: utorak | C33: srpanj | D33: x
A34: 46238 | B34: utorak | C34: kolovoz | D34: x
A35: 46245 | B35: utorak | C35: kolovoz | D35: x
A36: 46252 | B36: utorak | C36: kolovoz | D36: x | E36: x | F36: x
A37: 46259 | B37: utorak | C37: kolovoz | D37: x
A38: 46266 | B38: utorak | C38: rujan | D38: x
A39: 46273 | B39: utorak | C39: rujan | D39: x
A40: 46280 | B40: utorak | C40: rujan | D40: x | E40: x | F40: x
A41: 46287 | B41: utorak | C41: rujan | D41: x
...

Sheet Po vrsti
A1: Datum | B1: Dan | C1: Vrsta otpada | D1: Napomena
A2: 46029 | B2: srijeda | C2: Miješani komunalni otpad | D2: Pomaknuto zbog neradnog dana u tjednu
A3: 46035 | B3: utorak | C3: Miješani komunalni otpad
A4: 46042 | B4: utorak | C4: Miješani komunalni otpad
A5: 46042 | B5: utorak | C5: Plastika (vreća)
A6: 46042 | B6: utorak | C6: Papir (vreća)
A7: 46049 | B7: utorak | C7: Miješani komunalni otpad
A8: 46056 | B8: utorak | C8: Miješani komunalni otpad
A9: 46063 | B9: utorak | C9: Miješani komunalni otpad
A10: 46070 | B10: utorak | C10: Miješani komunalni otpad
A11: 46070 | B11: utorak | C11: Plastika (vreća)
A12: 46070 | B12: utorak | C12: Papir (vreća)
A13: 46077 | B13: utorak | C13: Miješani komunalni otpad
A14: 46084 | B14: utorak | C14: Miješani komunalni otpad
... A19: 46105 | B19: utorak | C19: Miješani komunalni otpad
A20: 46120 | B20: srijeda | C20: Miješani komunalni otpad | D20: Pomaknuto zbog neradnog dana u tjednu
A21: 46126 | B21: utorak | C21: Miješani komunalni otpad
A22: 46126 | B22: utorak | C22: Plastika (vreća)
A23: 46126 | B23: utorak | C23: Papir (vreća)
A24: 46133 | B24: utorak | C24: Miješani komunalni otpad
A25: 46140 | B25: utorak | C25: Miješani komunalni otpad
A26: 46147 | B26: utorak | C26: Miješani komunalni otpad
A27: 46154 | B27: utorak | C27: Miješani komunalni otpad
A28: 46154 | B28: utorak | C28: Plastika (vreća)
A29: 46154 | B29: utorak | C29: Papir (vreća)
A30: 46161 | B30: utorak | C30: Miješani komunalni otpad
A31: 46168 | B31: utorak | C31: Miješani komunalni otpad
A32: 46175 | B32: utorak | C32: Miješani komunalni otpad
... A34: 46189 | B34: utorak | C34: Miješani komunalni otpad
A35: 46197 | B35: srijeda | C35: Miješani komunalni otpad | D35: Pomaknuto zbog neradnog dana u tjednu
A36: 46197 | B36: srijeda | C36: Plastika (vreća) | D36: Pomaknuto zbog neradnog dana u tjednu
A37: 46197 | B37: srijeda | C37: Papir (vreća) | D37: Pomaknuto zbog neradnog dana u tjednu
A38: 46203 | B38: utorak | C38: Miješani komunalni otpad
A39: 46210 | B39: utorak | C39: Miješani komunalni otpad
A40: 46217 | B40: utorak | C40: Miješani komunalni otpad
A41: 46224 | B41: utorak | C41: Miješani komunalni otpad
A42: 46224 | B42: utorak | C42: Plastika (vreća)
A43: 46224 | B43: utorak | C43: Papir (vreća)
A44: 46224 | B44: utorak | C44: Glomazni otpad
A45: 46231 | B45: utorak | C45: Miješani komunalni otpad
...

Sheet Ulice i naselja
A1: Zona 10 (Cetingrad): ulice i naselja
A4: Ulica / naselje
A5: Cetingrad – uži centar
