Workbook

Sheet Pregled
A1: Zona 1, 2026: pregled odvoza
A3: Danas | B3: =TODAY()
A5: Vrsta otpada | B5: Sljedeći odvoz | C5: Dan | D5: Za dana | E5: Ukupno u 2026.
A6: Miješani komunalni otpad | B6: =IFERROR(1/(1/_xlfn.MINIFS(Raspored!$A$5:$A$77,Raspored!$D$5:$D$77,"x",Raspored!$A$5:$A$77,">="&$B$3)),"nema više u 2026.") | C6: =IF(ISNUMBER(B6),INDEX({"nedjelja","ponedjeljak","utorak","srijeda","četvrtak","petak","subota"},WEEKDAY(B6)),"") | D6: =IF(ISNUMBER(B6),B6-$B$3,"") | E6: =COUNTIF(Raspored!$D$5:$D$77,"x")
A7: Reciklabilni otpad (papir, plastika, metal) | B7: =IFERROR(1/(1/_xlfn.MINIFS(Raspored!$A$5:$A$77,Raspored!$E$5:$E$77,"x",Raspored!$A$5:$A$77,">="&$B$3)),"nema više u 2026.") | C7: =IF(ISNUMBER(B7),INDEX({"nedjelja","ponedjeljak","utorak","srijeda","četvrtak","petak","subota"},WEEKDAY(B7)),"") | D7: =IF(ISNUMBER(B7),B7-$B$3,"") | E7: =COUNTIF(Raspored!$E$5:$E$77,"x")
A9: Broj odvoza po mjesecu
A10: Mjesec | B10: Miješani komunalni otpad | C10: Reciklabilni otpad (papir, plastika, metal)
A11: siječanj | B11: =COUNTIFS(Raspored!$C$5:$C$77,$A11,Raspored!$D$5:$D$77,"x") | C11: =COUNTIFS(Raspored!$C$5:$C$77,$A11,Raspored!$E$5:$E$77,"x")
A12: veljača | B12: =COUNTIFS(Raspored!$C$5:$C$77,$A12,Raspored!$D$5:$D$77,"x") | C12: =COUNTIFS(Raspored!$C$5:$C$77,$A12,Raspored!$E$5:$E$77,"x")
A13: ožujak | B13: =COUNTIFS(Raspored!$C$5:$C$77,$A13,Raspored!$D$5:$D$77,"x") | C13: =COUNTIFS(Raspored!$C$5:$C$77,$A13,Raspored!$E$5:$E$77,"x")
A14: travanj | B14: =COUNTIFS(Raspored!$C$5:$C$77,$A14,Raspored!$D$5:$D$77,"x") | C14: =COUNTIFS(Raspored!$C$5:$C$77,$A14,Raspored!$E$5:$E$77,"x")
A15: svibanj | B15: =COUNTIFS(Raspored!$C$5:$C$77,$A15,Raspored!$D$5:$D$77,"x") | C15: =COUNTIFS(Raspored!$C$5:$C$77,$A15,Raspored!$E$5:$E$77,"x")
A16: lipanj | B16: =COUNTIFS(Raspored!$C$5:$C$77,$A16,Raspored!$D$5:$D$77,"x") | C16: =COUNTIFS(Raspored!$C$5:$C$77,$A16,Raspored!$E$5:$E$77,"x")
A17: srpanj | B17: =COUNTIFS(Raspored!$C$5:$C$77,$A17,Raspored!$D$5:$D$77,"x") | C17: =COUNTIFS(Raspored!$C$5:$C$77,$A17,Raspored!$E$5:$E$77,"x")
A18: kolovoz | B18: =COUNTIFS(Raspored!$C$5:$C$77,$A18,Raspored!$D$5:$D$77,"x") | C18: =COUNTIFS(Raspored!$C$5:$C$77,$A18,Raspored!$E$5:$E$77,"x")
A19: rujan | B19: =COUNTIFS(Raspored!$C$5:$C$77,$A19,Raspored!$D$5:$D$77,"x") | C19: =COUNTIFS(Raspored!$C$5:$C$77,$A19,Raspored!$E$5:$E$77,"x")
A20: listopad | B20: =COUNTIFS(Raspored!$C$5:$C$77,$A20,Raspored!$D$5:$D$77,"x") | C20: =COUNTIFS(Raspored!$C$5:$C$77,$A20,Raspored!$E$5:$E$77,"x")
A21: studeni | B21: =COUNTIFS(Raspored!$C$5:$C$77,$A21,Raspored!$D$5:$D$77,"x") | C21: =COUNTIFS(Raspored!$C$5:$C$77,$A21,Raspored!$E$5:$E$77,"x")
A22: prosinac | B22: =COUNTIFS(Raspored!$C$5:$C$77,$A22,Raspored!$D$5:$D$77,"x") | C22: =COUNTIFS(Raspored!$C$5:$C$77,$A22,Raspored!$E$5:$E$77,"x")
A23: Ukupno | B23: =SUM(B11:B22) | C23: =SUM(C11:C22)
A25: Napomene:
A26: • Miješani otpad – siječanj–travanj i listopad–prosinac: ponedjeljkom; svibanj–rujan: ponedjeljkom i četvrtkom. Reciklabilni otpad – siječanj–svibanj i listopad–prosinac: prvi ponedjeljak u mjesecu; lipanj–rujan: prvi i treći ponedjeljak u mjesecu.
A27: • Biootpad se na ovom području ne odvozi; preporučuje se kućno kompostiranje.
A28: • Raspored za kućanstva; za pravne osobe Leć objavljuje poseban raspored (nije uključen).
A29: • Staklo i tekstil: odvoz četvrtkom i petkom na poziv korisnika (tipizirane vrećice: Obala Juričev Ive Cota 9, Vodice).
A30: • Glomazni otpad: besplatno jednom godišnje do 4 m³ na zahtjev, tel. 022/443-787 ili info@lec.hr.
A31: • Do uspostave reciklažnog dvorišta otpad se može samostalno dovesti na adresu Put Gaćeleza 3/b, Vodice (pon–pet 7–14 h).
A32: • Okvirno vrijeme odvoza: zimi 6–13 h, ljeti 5–12 h.
A33: • Pomaci odvoza zbog blagdana nisu objavljeni kao pravilo; datumi su izračunati iz pravila, osim pomaka iz obavijesti tvrtke (označeni kao pomaknuti).
A34: • Sezone: miješani otpad (Vodice, Srima, Tribunj) zimi siječanj–travanj i listopad–prosinac jednom tjedno, ljeti svibanj–rujan dvaput tjedno; reciklabilni otpad zimi siječanj–svibanj i listopad–prosinac jednom mjesečno, ljeti lipanj–rujan dvaput mjesečno.

Sheet Raspored
A1: Raspored odvoza otpada 2026., Zona 1 (Vodice)
A2: "x" = odvoz tog dana. Spremnike iznijeti do 07:00. Prošli datumi su posivljeni.
A4: Datum | B4: Dan | C4: Mjesec | D4: Miješani komunalni otpad | E4: Reciklabilni otpad (papir, plastika, metal) | F4: Napomena
A5: 46027 | B5: ponedjeljak | C5: siječanj | D5: x | E5: x
A6: 46034 | B6: ponedjeljak | C6: siječanj | D6: x
A7: 46041 | B7: ponedjeljak | C7: siječanj | D7: x
A8: 46048 | B8: ponedjeljak | C8: siječanj | D8: x
A9: 46055 | B9: ponedjeljak | C9: veljača | D9: x | E9: x
A10: 46062 | B10: ponedjeljak | C10: veljača | D10: x
A11: 46069 | B11: ponedjeljak | C11: veljača | D11: x
A12: 46076 | B12: ponedjeljak | C12: veljača | D12: x
A13: 46083 | B13: ponedjeljak | C13: ožujak | D13: x | E13: x
A14: 46090 | B14: ponedjeljak | C14: ožujak | D14: x
A15: 46097 | B15: ponedjeljak | C15: ožujak | D15: x
A16: 46104 | B16: ponedjeljak | C16: ožujak | D16: x
A17: 46111 | B17: ponedjeljak | C17: ožujak | D17: x
A18: 46118 | B18: ponedjeljak | C18: travanj | D18: x | E18: x
A19: 46125 | B19: ponedjeljak | C19: travanj | D19: x
A20: 46132 | B20: ponedjeljak | C20: travanj | D20: x
A21: 46139 | B21: ponedjeljak | C21: travanj | D21: x
A22: 46146 | B22: ponedjeljak | C22: svibanj | D22: x | E22: x
A23: 46149 | B23: četvrtak | C23: svibanj | D23: x
A24: 46153 | B24: ponedjeljak | C24: svibanj | D24: x
A25: 46156 | B25: četvrtak | C25: svibanj | D25: x
A26: 46160 | B26: ponedjeljak | C26: svibanj | D26: x
A27: 46163 | B27: četvrtak | C27: svibanj | D27: x
A28: 46167 | B28: ponedjeljak | C28: svibanj | D28: x
A29: 46170 | B29: četvrtak | C29: svibanj | D29: x
A30: 46174 | B30: ponedjeljak | C30: lipanj | D30: x | E30: x
A31: 46177 | B31: četvrtak | C31: lipanj | D31: x
A32: 46181 | B32: ponedjeljak | C32: lipanj | D32: x
A33: 46184 | B33: četvrtak | C33: lipanj | D33: x
A34: 46188 | B34: ponedjeljak | C34: lipanj | D34: x | E34: x
A35: 46191 | B35: četvrtak | C35: lipanj | D35: x
A36: 46195 | B36: ponedjeljak | C36: lipanj | D36: x
A37: 46198 | B37: četvrtak | C37: lipanj | D37: x
A38: 46202 | B38: ponedjeljak | C38: lipanj | D38: x
A39: 46205 | B39: četvrtak | C39: srpanj | D39: x
A40: 46209 | B40: ponedjeljak | C40: srpanj | D40: x | E40: x
A41: 46212 | B41: četvrtak | C41: srpanj | D41: x
...

Sheet Po vrsti
A1: Datum | B1: Dan | C1: Vrsta otpada | D1: Napomena
A2: 46027 | B2: ponedjeljak | C2: Miješani komunalni otpad
A3: 46027 | B3: ponedjeljak | C3: Reciklabilni otpad (papir, plastika, metal)
A4: 46034 | B4: ponedjeljak | C4: Miješani komunalni otpad
A5: 46041 | B5: ponedjeljak | C5: Miješani komunalni otpad
A6: 46048 | B6: ponedjeljak | C6: Miješani komunalni otpad
A7: 46055 | B7: ponedjeljak | C7: Miješani komunalni otpad
A8: 46055 | B8: ponedjeljak | C8: Reciklabilni otpad (papir, plastika, metal)
A9: 46062 | B9: ponedjeljak | C9: Miješani komunalni otpad
A10: 46069 | B10: ponedjeljak | C10: Miješani komunalni otpad
A11: 46076 | B11: ponedjeljak | C11: Miješani komunalni otpad
A12: 46083 | B12: ponedjeljak | C12: Miješani komunalni otpad
A13: 46083 | B13: ponedjeljak | C13: Reciklabilni otpad (papir, plastika, metal)
... A90: 46384 | B90: ponedjeljak | C90: Miješani komunalni otpad

Sheet Ulice i naselja
A1: Zona 1 (Vodice): ulice i naselja
A4: Ulica / naselje
A5: Andrije Kačića Miošića
A6: Augusta Šenoe
A7: Ante Kovačića
A8: Antuna Mihanovića
A9: Bilan Šime Šijca
A10: Brodska
A11: Benjamina Udovičića
A12: Ćirila i Metoda
A13: Eugena Kumičića
A14: Eugena Kvaternika
... A53: Zagrebačka
