Workbook

Sheet Pregled
A1: Zona 8, 2026: pregled odvoza
A3: Danas | B3: =TODAY()
A5: Vrsta otpada | B5: Sljedeći odvoz | C5: Dan | D5: Za dana | E5: Ukupno u 2026.
A6: Miješani komunalni otpad | B6: =IFERROR(1/(1/_xlfn.MINIFS(Raspored!$A$5:$A$78,Raspored!$D$5:$D$78,"x",Raspored!$A$5:$A$78,">="&$B$3)),"nema više u 2026.") | C6: =IF(ISNUMBER(B6),INDEX({"nedjelja","ponedjeljak","utorak","srijeda","četvrtak","petak","subota"},WEEKDAY(B6)),"") | D6: =IF(ISNUMBER(B6),B6-$B$3,"") | E6: =COUNTIF(Raspored!$D$5:$D$78,"x")
A7: Biootpad | B7: =IFERROR(1/(1/_xlfn.MINIFS(Raspored!$A$5:$A$78,Raspored!$E$5:$E$78,"x",Raspored!$A$5:$A$78,">="&$B$3)),"nema više u 2026.") | C7: =IF(ISNUMBER(B7),INDEX({"nedjelja","ponedjeljak","utorak","srijeda","četvrtak","petak","subota"},WEEKDAY(B7)),"") | D7: =IF(ISNUMBER(B7),B7-$B$3,"") | E7: =COUNTIF(Raspored!$E$5:$E$78,"x")
A8: Reciklabilni otpad (papir, karton, plastika, metal) | B8: =IFERROR(1/(1/_xlfn.MINIFS(Raspored!$A$5:$A$78,Raspored!$F$5:$F$78,"x",Raspored!$A$5:$A$78,">="&$B$3)),"nema više u 2026.") | C8: =IF(ISNUMBER(B8),INDEX({"nedjelja","ponedjeljak","utorak","srijeda","četvrtak","petak","subota"},WEEKDAY(B8)),"") | D8: =IF(ISNUMBER(B8),B8-$B$3,"") | E8: =COUNTIF(Raspored!$F$5:$F$78,"x")
A10: Broj odvoza po mjesecu
A11: Mjesec | B11: Miješani komunalni otpad | C11: Biootpad | D11: Reciklabilni otpad (papir, karton, plastika, metal)
A12: siječanj | B12: =COUNTIFS(Raspored!$C$5:$C$78,$A12,Raspored!$D$5:$D$78,"x") | C12: =COUNTIFS(Raspored!$C$5:$C$78,$A12,Raspored!$E$5:$E$78,"x") | D12: =COUNTIFS(Raspored!$C$5:$C$78,$A12,Raspored!$F$5:$F$78,"x")
A13: veljača | B13: =COUNTIFS(Raspored!$C$5:$C$78,$A13,Raspored!$D$5:$D$78,"x") | C13: =COUNTIFS(Raspored!$C$5:$C$78,$A13,Raspored!$E$5:$E$78,"x") | D13: =COUNTIFS(Raspored!$C$5:$C$78,$A13,Raspored!$F$5:$F$78,"x")
A14: ožujak | B14: =COUNTIFS(Raspored!$C$5:$C$78,$A14,Raspored!$D$5:$D$78,"x") | C14: =COUNTIFS(Raspored!$C$5:$C$78,$A14,Raspored!$E$5:$E$78,"x") | D14: =COUNTIFS(Raspored!$C$5:$C$78,$A14,Raspored!$F$5:$F$78,"x")
A15: travanj | B15: =COUNTIFS(Raspored!$C$5:$C$78,$A15,Raspored!$D$5:$D$78,"x") | C15: =COUNTIFS(Raspored!$C$5:$C$78,$A15,Raspored!$E$5:$E$78,"x") | D15: =COUNTIFS(Raspored!$C$5:$C$78,$A15,Raspored!$F$5:$F$78,"x")
A16: svibanj | B16: =COUNTIFS(Raspored!$C$5:$C$78,$A16,Raspored!$D$5:$D$78,"x") | C16: =COUNTIFS(Raspored!$C$5:$C$78,$A16,Raspored!$E$5:$E$78,"x") | D16: =COUNTIFS(Raspored!$C$5:$C$78,$A16,Raspored!$F$5:$F$78,"x")
A17: lipanj | B17: =COUNTIFS(Raspored!$C$5:$C$78,$A17,Raspored!$D$5:$D$78,"x") | C17: =COUNTIFS(Raspored!$C$5:$C$78,$A17,Raspored!$E$5:$E$78,"x") | D17: =COUNTIFS(Raspored!$C$5:$C$78,$A17,Raspored!$F$5:$F$78,"x")
A18: srpanj | B18: =COUNTIFS(Raspored!$C$5:$C$78,$A18,Raspored!$D$5:$D$78,"x") | C18: =COUNTIFS(Raspored!$C$5:$C$78,$A18,Raspored!$E$5:$E$78,"x") | D18: =COUNTIFS(Raspored!$C$5:$C$78,$A18,Raspored!$F$5:$F$78,"x")
A19: kolovoz | B19: =COUNTIFS(Raspored!$C$5:$C$78,$A19,Raspored!$D$5:$D$78,"x") | C19: =COUNTIFS(Raspored!$C$5:$C$78,$A19,Raspored!$E$5:$E$78,"x") | D19: =COUNTIFS(Raspored!$C$5:$C$78,$A19,Raspored!$F$5:$F$78,"x")
A20: rujan | B20: =COUNTIFS(Raspored!$C$5:$C$78,$A20,Raspored!$D$5:$D$78,"x") | C20: =COUNTIFS(Raspored!$C$5:$C$78,$A20,Raspored!$E$5:$E$78,"x") | D20: =COUNTIFS(Raspored!$C$5:$C$78,$A20,Raspored!$F$5:$F$78,"x")
A21: listopad | B21: =COUNTIFS(Raspored!$C$5:$C$78,$A21,Raspored!$D$5:$D$78,"x") | C21: =COUNTIFS(Raspored!$C$5:$C$78,$A21,Raspored!$E$5:$E$78,"x") | D21: =COUNTIFS(Raspored!$C$5:$C$78,$A21,Raspored!$F$5:$F$78,"x")
A22: studeni | B22: =COUNTIFS(Raspored!$C$5:$C$78,$A22,Raspored!$D$5:$D$78,"x") | C22: =COUNTIFS(Raspored!$C$5:$C$78,$A22,Raspored!$E$5:$E$78,"x") | D22: =COUNTIFS(Raspored!$C$5:$C$78,$A22,Raspored!$F$5:$F$78,"x")
A23: prosinac | B23: =COUNTIFS(Raspored!$C$5:$C$78,$A23,Raspored!$D$5:$D$78,"x") | C23: =COUNTIFS(Raspored!$C$5:$C$78,$A23,Raspored!$E$5:$E$78,"x") | D23: =COUNTIFS(Raspored!$C$5:$C$78,$A23,Raspored!$F$5:$F$78,"x")
A24: Ukupno | B24: =SUM(B12:B23) | C24: =SUM(C12:C23) | D24: =SUM(D12:D23)
A26: Napomene:
A27: • Miješani i reciklabilni otpad srijedom. Biootpad: od 1.10. do 30.4. srijedom, od 1.5. do 30.9. srijedom i subotom. Uz redovni odvoz reciklabilnog otpada u neparnim tjednima i izvanredni odvoz u parnim tjednima (Kalendar izvanrednog odvoza reciklabilnog otpada).
A28: • Biootpad se od 1.10. do 30.4. odvozi jednom, a od 1.5. do 30.9. dvaput tjedno.
A29: • Miješani komunalni otpad odvozi se jednom tjedno na dan područja; reciklabilni otpad (papir, karton, plastika i metalna ambalaža u istom spremniku) jednom u dva tjedna – u Opatiji i Lovranu u neparnim, u Matuljima i Mošćeničkoj Dragi u parnim tjednima.
A30: • U Lovranu, Matuljima i Mošćeničkoj Dragi staklena ambalaža odvozi se prvi tjedan u mjesecu, uz odvoz reciklabilnog otpada, u prozirnim vrećicama pored spremnika.
A31: • Blagdani su ucrtani u kalendare: crveno polje je neradni dan bez odvoza, a odvoz se obavlja dan na koji pokazuje strelica (u ovim podacima označen kao pomaknut). Na ostale blagdane otpad se odvozi redovno.
A32: • Otpad se odlaže na dan prikupljanja najkasnije do 5:00 sati u naseljima Opatija, Ičići i Ika, a drugdje do 7:00 sati, isključivo u spremnike ili vrećice davatelja usluge.
A33: • Upiti: info@komunalac-opatija.hr, 051 505 201 (interno 2).
A34: • Na dijelu Grada Opatije reciklabilni otpad odvozi se svaki tjedan (Kalendar izvanrednog odvoza reciklabilnog otpada: https://www.komunalac-opatija.hr/wp-content/uploads/2025/12/Kalendar-odvoza-izvanrednog-reciklabilnog-Opatija-2026.pdf); te ulice imaju zasebne zone.
A35: • U Lovranu (područje „ispod groblja”) od srpnja do listopada reciklabilni otpad odvozi se i izvanredno utorkom: https://www.komunalac-opatija.hr/wp-content/uploads/2026/07/Kalendar-odvoza-izvanrednog-reciklabilnog-otpada-Lovran-2026.pdf
A36: • Mobilno reciklažno dvorište Grada Opatije obilazi naselja po tjednima: https://www.komunalac-opatija.hr/wp-content/uploads/2025/12/Raspored-postave-MRD-Opatija-2026.pdf

Sheet Raspored
A1: Raspored odvoza otpada 2026., Zona 8 (Opatija)
A2: "x" = odvoz tog dana. Spremnike iznijeti do 07:00. Prošli datumi su posivljeni.
A4: Datum | B4: Dan | C4: Mjesec | D4: Miješani komunalni otpad | E4: Biootpad | F4: Reciklabilni otpad (papir, karton, plastika, metal) | G4: Napomena
A5: 46029 | B5: srijeda | C5: siječanj | D5: x | E5: x | F5: x
A6: 46036 | B6: srijeda | C6: siječanj | D6: x | E6: x | F6: x
A7: 46043 | B7: srijeda | C7: siječanj | D7: x | E7: x | F7: x
A8: 46050 | B8: srijeda | C8: siječanj | D8: x | E8: x | F8: x
A9: 46057 | B9: srijeda | C9: veljača | D9: x | E9: x | F9: x
A10: 46064 | B10: srijeda | C10: veljača | D10: x | E10: x | F10: x
A11: 46071 | B11: srijeda | C11: veljača | D11: x | E11: x | F11: x
A12: 46078 | B12: srijeda | C12: veljača | D12: x | E12: x | F12: x
A13: 46085 | B13: srijeda | C13: ožujak | D13: x | E13: x | F13: x
A14: 46092 | B14: srijeda | C14: ožujak | D14: x | E14: x | F14: x
A15: 46099 | B15: srijeda | C15: ožujak | D15: x | E15: x | F15: x
A16: 46106 | B16: srijeda | C16: ožujak | D16: x | E16: x | F16: x
... A21: 46141 | B21: srijeda | C21: travanj | D21: x | E21: x | F21: x
A22: 46144 | B22: subota | C22: svibanj | E22: x
A23: 46148 | B23: srijeda | C23: svibanj | D23: x | E23: x | F23: x
A24: 46151 | B24: subota | C24: svibanj | E24: x
A25: 46155 | B25: srijeda | C25: svibanj | D25: x | E25: x | F25: x
A26: 46158 | B26: subota | C26: svibanj | E26: x
A27: 46162 | B27: srijeda | C27: svibanj | D27: x | E27: x | F27: x
A28: 46165 | B28: subota | C28: svibanj | E28: x
A29: 46169 | B29: srijeda | C29: svibanj | D29: x | E29: x | F29: x
A30: 46172 | B30: subota | C30: svibanj | E30: x
A31: 46176 | B31: srijeda | C31: lipanj | D31: x | E31: x | F31: x
A32: 46179 | B32: subota | C32: lipanj | E32: x
A33: 46183 | B33: srijeda | C33: lipanj | D33: x | E33: x | F33: x
A34: 46186 | B34: subota | C34: lipanj | E34: x
A35: 46190 | B35: srijeda | C35: lipanj | D35: x | E35: x | F35: x
A36: 46193 | B36: subota | C36: lipanj | E36: x
A37: 46197 | B37: srijeda | C37: lipanj | D37: x | E37: x | F37: x
A38: 46200 | B38: subota | C38: lipanj | E38: x
A39: 46204 | B39: srijeda | C39: srpanj | D39: x | E39: x | F39: x
A40: 46207 | B40: subota | C40: srpanj | E40: x
A41: 46211 | B41: srijeda | C41: srpanj | D41: x | E41: x | F41: x
A42: 46214 | B42: subota | C42: srpanj | E42: x
A43: 46218 | B43: srijeda | C43: srpanj | D43: x | E43: x | F43: x
A44: 46221 | B44: subota | C44: srpanj | E44: x
A45: 46225 | B45: srijeda | C45: srpanj | D45: x | E45: x | F45: x
...

Sheet Po vrsti
A1: Datum | B1: Dan | C1: Vrsta otpada | D1: Napomena
A2: 46029 | B2: srijeda | C2: Miješani komunalni otpad
A3: 46029 | B3: srijeda | C3: Biootpad
A4: 46029 | B4: srijeda | C4: Reciklabilni otpad (papir, karton, plastika, metal)
A5: 46036 | B5: srijeda | C5: Miješani komunalni otpad
A6: 46036 | B6: srijeda | C6: Biootpad
A7: 46036 | B7: srijeda | C7: Reciklabilni otpad (papir, karton, plastika, metal)
A8: 46043 | B8: srijeda | C8: Miješani komunalni otpad
A9: 46043 | B9: srijeda | C9: Biootpad
A10: 46043 | B10: srijeda | C10: Reciklabilni otpad (papir, karton, plastika, metal)
A11: 46050 | B11: srijeda | C11: Miješani komunalni otpad
A12: 46050 | B12: srijeda | C12: Biootpad
A13: 46050 | B13: srijeda | C13: Reciklabilni otpad (papir, karton, plastika, metal)
... A179: 46386 | B179: srijeda | C179: Reciklabilni otpad (papir, karton, plastika, metal)

Sheet Ulice i naselja
A1: Zona 8 (Opatija): ulice i naselja
A2: Volosko (bez Tošine), Opatija centar do Slatine (sve osim hotela i restorana, te svih pravnih subjekata kojima je reciklabilni otpad nastao iz proizvodne djelatnosti)
A4: Ulica / naselje
A5: Volosko (bez Tošine)
A6: Opatija centar do Slatine (sve osim hotela i restorana, te svih pravnih subjekata kojima je reciklabilni otpad nastao iz proizvodne djelatnosti)
