Workbook

Sheet Pregled
A1: Zona 6, 2026: pregled odvoza
A3: Danas | B3: =TODAY()
A5: Vrsta otpada | B5: Sljedeći odvoz | C5: Dan | D5: Za dana | E5: Ukupno u 2026.
A6: Miješani komunalni otpad | B6: =IFERROR(1/(1/_xlfn.MINIFS(Raspored!$A$5:$A$62,Raspored!$D$5:$D$62,"x",Raspored!$A$5:$A$62,">="&$B$3)),"nema više u 2026.") | C6: =IF(ISNUMBER(B6),INDEX({"nedjelja","ponedjeljak","utorak","srijeda","četvrtak","petak","subota"},WEEKDAY(B6)),"") | D6: =IF(ISNUMBER(B6),B6-$B$3,"") | E6: =COUNTIF(Raspored!$D$5:$D$62,"x")
A7: Plastika i metal | B7: =IFERROR(1/(1/_xlfn.MINIFS(Raspored!$A$5:$A$62,Raspored!$E$5:$E$62,"x",Raspored!$A$5:$A$62,">="&$B$3)),"nema više u 2026.") | C7: =IF(ISNUMBER(B7),INDEX({"nedjelja","ponedjeljak","utorak","srijeda","četvrtak","petak","subota"},WEEKDAY(B7)),"") | D7: =IF(ISNUMBER(B7),B7-$B$3,"") | E7: =COUNTIF(Raspored!$E$5:$E$62,"x")
A8: Papir i karton | B8: =IFERROR(1/(1/_xlfn.MINIFS(Raspored!$A$5:$A$62,Raspored!$F$5:$F$62,"x",Raspored!$A$5:$A$62,">="&$B$3)),"nema više u 2026.") | C8: =IF(ISNUMBER(B8),INDEX({"nedjelja","ponedjeljak","utorak","srijeda","četvrtak","petak","subota"},WEEKDAY(B8)),"") | D8: =IF(ISNUMBER(B8),B8-$B$3,"") | E8: =COUNTIF(Raspored!$F$5:$F$62,"x")
A9: Staklo | B9: =IFERROR(1/(1/_xlfn.MINIFS(Raspored!$A$5:$A$62,Raspored!$G$5:$G$62,"x",Raspored!$A$5:$A$62,">="&$B$3)),"nema više u 2026.") | C9: =IF(ISNUMBER(B9),INDEX({"nedjelja","ponedjeljak","utorak","srijeda","četvrtak","petak","subota"},WEEKDAY(B9)),"") | D9: =IF(ISNUMBER(B9),B9-$B$3,"") | E9: =COUNTIF(Raspored!$G$5:$G$62,"x")
A10: Metal | B10: =IFERROR(1/(1/_xlfn.MINIFS(Raspored!$A$5:$A$62,Raspored!$H$5:$H$62,"x",Raspored!$A$5:$A$62,">="&$B$3)),"nema više u 2026.") | C10: =IF(ISNUMBER(B10),INDEX({"nedjelja","ponedjeljak","utorak","srijeda","četvrtak","petak","subota"},WEEKDAY(B10)),"") | D10: =IF(ISNUMBER(B10),B10-$B$3,"") | E10: =COUNTIF(Raspored!$H$5:$H$62,"x")
A12: Broj odvoza po mjesecu
A13: Mjesec | B13: Miješani komunalni otpad | C13: Plastika i metal | D13: Papir i karton | E13: Staklo | F13: Metal
A14: siječanj | B14: =COUNTIFS(Raspored!$C$5:$C$62,$A14,Raspored!$D$5:$D$62,"x") | C14: =COUNTIFS(Raspored!$C$5:$C$62,$A14,Raspored!$E$5:$E$62,"x") | D14: =COUNTIFS(Raspored!$C$5:$C$62,$A14,Raspored!$F$5:$F$62,"x") | E14: =COUNTIFS(Raspored!$C$5:$C$62,$A14,Raspored!$G$5:$G$62,"x") | F14: =COUNTIFS(Raspored!$C$5:$C$62,$A14,Raspored!$H$5:$H$62,"x")
A15: veljača | B15: =COUNTIFS(Raspored!$C$5:$C$62,$A15,Raspored!$D$5:$D$62,"x") | C15: =COUNTIFS(Raspored!$C$5:$C$62,$A15,Raspored!$E$5:$E$62,"x") | D15: =COUNTIFS(Raspored!$C$5:$C$62,$A15,Raspored!$F$5:$F$62,"x") | E15: =COUNTIFS(Raspored!$C$5:$C$62,$A15,Raspored!$G$5:$G$62,"x") | F15: =COUNTIFS(Raspored!$C$5:$C$62,$A15,Raspored!$H$5:$H$62,"x")
A16: ožujak | B16: =COUNTIFS(Raspored!$C$5:$C$62,$A16,Raspored!$D$5:$D$62,"x") | C16: =COUNTIFS(Raspored!$C$5:$C$62,$A16,Raspored!$E$5:$E$62,"x") | D16: =COUNTIFS(Raspored!$C$5:$C$62,$A16,Raspored!$F$5:$F$62,"x") | E16: =COUNTIFS(Raspored!$C$5:$C$62,$A16,Raspored!$G$5:$G$62,"x") | F16: =COUNTIFS(Raspored!$C$5:$C$62,$A16,Raspored!$H$5:$H$62,"x")
A17: travanj | B17: =COUNTIFS(Raspored!$C$5:$C$62,$A17,Raspored!$D$5:$D$62,"x") | C17: =COUNTIFS(Raspored!$C$5:$C$62,$A17,Raspored!$E$5:$E$62,"x") | D17: =COUNTIFS(Raspored!$C$5:$C$62,$A17,Raspored!$F$5:$F$62,"x") | E17: =COUNTIFS(Raspored!$C$5:$C$62,$A17,Raspored!$G$5:$G$62,"x") | F17: =COUNTIFS(Raspored!$C$5:$C$62,$A17,Raspored!$H$5:$H$62,"x")
A18: svibanj | B18: =COUNTIFS(Raspored!$C$5:$C$62,$A18,Raspored!$D$5:$D$62,"x") | C18: =COUNTIFS(Raspored!$C$5:$C$62,$A18,Raspored!$E$5:$E$62,"x") | D18: =COUNTIFS(Raspored!$C$5:$C$62,$A18,Raspored!$F$5:$F$62,"x") | E18: =COUNTIFS(Raspored!$C$5:$C$62,$A18,Raspored!$G$5:$G$62,"x") | F18: =COUNTIFS(Raspored!$C$5:$C$62,$A18,Raspored!$H$5:$H$62,"x")
A19: lipanj | B19: =COUNTIFS(Raspored!$C$5:$C$62,$A19,Raspored!$D$5:$D$62,"x") | C19: =COUNTIFS(Raspored!$C$5:$C$62,$A19,Raspored!$E$5:$E$62,"x") | D19: =COUNTIFS(Raspored!$C$5:$C$62,$A19,Raspored!$F$5:$F$62,"x") | E19: =COUNTIFS(Raspored!$C$5:$C$62,$A19,Raspored!$G$5:$G$62,"x") | F19: =COUNTIFS(Raspored!$C$5:$C$62,$A19,Raspored!$H$5:$H$62,"x")
A20: srpanj | B20: =COUNTIFS(Raspored!$C$5:$C$62,$A20,Raspored!$D$5:$D$62,"x") | C20: =COUNTIFS(Raspored!$C$5:$C$62,$A20,Raspored!$E$5:$E$62,"x") | D20: =COUNTIFS(Raspored!$C$5:$C$62,$A20,Raspored!$F$5:$F$62,"x") | E20: =COUNTIFS(Raspored!$C$5:$C$62,$A20,Raspored!$G$5:$G$62,"x") | F20: =COUNTIFS(Raspored!$C$5:$C$62,$A20,Raspored!$H$5:$H$62,"x")
A21: kolovoz | B21: =COUNTIFS(Raspored!$C$5:$C$62,$A21,Raspored!$D$5:$D$62,"x") | C21: =COUNTIFS(Raspored!$C$5:$C$62,$A21,Raspored!$E$5:$E$62,"x") | D21: =COUNTIFS(Raspored!$C$5:$C$62,$A21,Raspored!$F$5:$F$62,"x") | E21: =COUNTIFS(Raspored!$C$5:$C$62,$A21,Raspored!$G$5:$G$62,"x") | F21: =COUNTIFS(Raspored!$C$5:$C$62,$A21,Raspored!$H$5:$H$62,"x")
A22: rujan | B22: =COUNTIFS(Raspored!$C$5:$C$62,$A22,Raspored!$D$5:$D$62,"x") | C22: =COUNTIFS(Raspored!$C$5:$C$62,$A22,Raspored!$E$5:$E$62,"x") | D22: =COUNTIFS(Raspored!$C$5:$C$62,$A22,Raspored!$F$5:$F$62,"x") | E22: =COUNTIFS(Raspored!$C$5:$C$62,$A22,Raspored!$G$5:$G$62,"x") | F22: =COUNTIFS(Raspored!$C$5:$C$62,$A22,Raspored!$H$5:$H$62,"x")
A23: listopad | B23: =COUNTIFS(Raspored!$C$5:$C$62,$A23,Raspored!$D$5:$D$62,"x") | C23: =COUNTIFS(Raspored!$C$5:$C$62,$A23,Raspored!$E$5:$E$62,"x") | D23: =COUNTIFS(Raspored!$C$5:$C$62,$A23,Raspored!$F$5:$F$62,"x") | E23: =COUNTIFS(Raspored!$C$5:$C$62,$A23,Raspored!$G$5:$G$62,"x") | F23: =COUNTIFS(Raspored!$C$5:$C$62,$A23,Raspored!$H$5:$H$62,"x")
A24: studeni | B24: =COUNTIFS(Raspored!$C$5:$C$62,$A24,Raspored!$D$5:$D$62,"x") | C24: =COUNTIFS(Raspored!$C$5:$C$62,$A24,Raspored!$E$5:$E$62,"x") | D24: =COUNTIFS(Raspored!$C$5:$C$62,$A24,Raspored!$F$5:$F$62,"x") | E24: =COUNTIFS(Raspored!$C$5:$C$62,$A24,Raspored!$G$5:$G$62,"x") | F24: =COUNTIFS(Raspored!$C$5:$C$62,$A24,Raspored!$H$5:$H$62,"x")
A25: prosinac | B25: =COUNTIFS(Raspored!$C$5:$C$62,$A25,Raspored!$D$5:$D$62,"x") | C25: =COUNTIFS(Raspored!$C$5:$C$62,$A25,Raspored!$E$5:$E$62,"x") | D25: =COUNTIFS(Raspored!$C$5:$C$62,$A25,Raspored!$F$5:$F$62,"x") | E25: =COUNTIFS(Raspored!$C$5:$C$62,$A25,Raspored!$G$5:$G$62,"x") | F25: =COUNTIFS(Raspored!$C$5:$C$62,$A25,Raspored!$H$5:$H$62,"x")
A26: Ukupno | B26: =SUM(B14:B25) | C26: =SUM(C14:C25) | D26: =SUM(D14:D25) | E26: =SUM(E14:E25) | F26: =SUM(F14:F25)
A28: Napomene:
A29: • Biootpad se na ovom području ne odvozi; preporučuje se kućno kompostiranje.
A30: • Miješani komunalni otpad odvozi se svaka dva tjedna; papir, plastika te staklo ili metal (izmjenjuju se po mjesecima) prema mjesečnom rasporedu razvrstanog otpada.
A31: • Pomaci odvoza zbog blagdana nisu objavljeni: datumi su preneseni kako su u rasporedu (npr. 01.01. je naveden kao redovni dan odvoza miješanog otpada). Provjerite obavijesti na baranjskacistoca.hr.
A32: • Kontakt: 031 700 810, info@baranjskacistoca.hr (Ulica Republike 11, Beli Manastir).
A33: • Izvor rasporeda: https://baranjskacistoca.hr/wp-content/uploads/2026/01/Rasporedi-2026.xlsx (poveznica na https://baranjskacistoca.hr/redovni-odvoz/).

Sheet Raspored
A1: Raspored odvoza otpada 2026., Zona 6 (Kneževi Vinogradi)
A2: "x" = odvoz tog dana. Spremnike iznijeti do 07:00. Prošli datumi su posivljeni.
A4: Datum | B4: Dan | C4: Mjesec | D4: Miješani komunalni otpad | E4: Plastika i metal | F4: Papir i karton | G4: Staklo | H4: Metal | I4: Napomena
A5: 46034 | B5: ponedjeljak | C5: siječanj | D5: x
A6: 46043 | B6: srijeda | C6: siječanj | F6: x
A7: 46048 | B7: ponedjeljak | C7: siječanj | D7: x
A8: 46050 | B8: srijeda | C8: siječanj | E8: x
A9: 46062 | B9: ponedjeljak | C9: veljača | D9: x
A10: 46064 | B10: srijeda | C10: veljača | F10: x
A11: 46071 | B11: srijeda | C11: veljača | E11: x
A12: 46076 | B12: ponedjeljak | C12: veljača | D12: x
A13: 46078 | B13: srijeda | C13: veljača | G13: x
A14: 46090 | B14: ponedjeljak | C14: ožujak | D14: x
A15: 46092 | B15: srijeda | C15: ožujak | F15: x
A16: 46099 | B16: srijeda | C16: ožujak | E16: x
A17: 46104 | B17: ponedjeljak | C17: ožujak | D17: x
A18: 46106 | B18: srijeda | C18: ožujak | H18: x
A19: 46118 | B19: ponedjeljak | C19: travanj | D19: x
A20: 46127 | B20: srijeda | C20: travanj | F20: x
A21: 46132 | B21: ponedjeljak | C21: travanj | D21: x
A22: 46134 | B22: srijeda | C22: travanj | E22: x
A23: 46146 | B23: ponedjeljak | C23: svibanj | D23: x
A24: 46148 | B24: srijeda | C24: svibanj | F24: x
A25: 46155 | B25: srijeda | C25: svibanj | E25: x
A26: 46160 | B26: ponedjeljak | C26: svibanj | D26: x
A27: 46162 | B27: srijeda | C27: svibanj | G27: x
A28: 46174 | B28: ponedjeljak | C28: lipanj | D28: x
A29: 46183 | B29: srijeda | C29: lipanj | F29: x
A30: 46188 | B30: ponedjeljak | C30: lipanj | D30: x
A31: 46190 | B31: srijeda | C31: lipanj | E31: x
A32: 46197 | B32: srijeda | C32: lipanj | H32: x
A33: 46202 | B33: ponedjeljak | C33: lipanj | D33: x
A34: 46204 | B34: srijeda | C34: srpanj | F34: x
A35: 46211 | B35: srijeda | C35: srpanj | E35: x
A36: 46216 | B36: ponedjeljak | C36: srpanj | D36: x
A37: 46230 | B37: ponedjeljak | C37: srpanj | D37: x
A38: 46244 | B38: ponedjeljak | C38: kolovoz | D38: x
A39: 46253 | B39: srijeda | C39: kolovoz | F39: x
A40: 46258 | B40: ponedjeljak | C40: kolovoz | D40: x
A41: 46260 | B41: srijeda | C41: kolovoz | E41: x
...

Sheet Po vrsti
A1: Datum | B1: Dan | C1: Vrsta otpada | D1: Napomena
A2: 46034 | B2: ponedjeljak | C2: Miješani komunalni otpad
A3: 46043 | B3: srijeda | C3: Papir i karton
A4: 46048 | B4: ponedjeljak | C4: Miješani komunalni otpad
A5: 46050 | B5: srijeda | C5: Plastika i metal
A6: 46062 | B6: ponedjeljak | C6: Miješani komunalni otpad
A7: 46064 | B7: srijeda | C7: Papir i karton
A8: 46071 | B8: srijeda | C8: Plastika i metal
A9: 46076 | B9: ponedjeljak | C9: Miješani komunalni otpad
A10: 46078 | B10: srijeda | C10: Staklo
A11: 46090 | B11: ponedjeljak | C11: Miješani komunalni otpad
A12: 46092 | B12: srijeda | C12: Papir i karton
A13: 46099 | B13: srijeda | C13: Plastika i metal
... A59: 46384 | B59: ponedjeljak | C59: Miješani komunalni otpad

Sheet Ulice i naselja
A1: Zona 6 (Kneževi Vinogradi): ulice i naselja
A4: Ulica / naselje
A5: Kneževi Vinogradi (cijela općina)
