Workbook

Sheet Pregled
A1: Zona 57, 2026: pregled odvoza
A3: Danas | B3: =TODAY()
A5: Vrsta otpada | B5: Sljedeći odvoz | C5: Dan | D5: Za dana | E5: Ukupno u 2026.
A6: Miješani komunalni otpad | B6: =IFERROR(1/(1/_xlfn.MINIFS(Raspored!$A$5:$A$88,Raspored!$D$5:$D$88,"x",Raspored!$A$5:$A$88,">="&$B$3)),"nema više u 2026.") | C6: =IF(ISNUMBER(B6),INDEX({"nedjelja","ponedjeljak","utorak","srijeda","četvrtak","petak","subota"},WEEKDAY(B6)),"") | D6: =IF(ISNUMBER(B6),B6-$B$3,"") | E6: =COUNTIF(Raspored!$D$5:$D$88,"x")
A7: Plastika i metal | B7: =IFERROR(1/(1/_xlfn.MINIFS(Raspored!$A$5:$A$88,Raspored!$E$5:$E$88,"x",Raspored!$A$5:$A$88,">="&$B$3)),"nema više u 2026.") | C7: =IF(ISNUMBER(B7),INDEX({"nedjelja","ponedjeljak","utorak","srijeda","četvrtak","petak","subota"},WEEKDAY(B7)),"") | D7: =IF(ISNUMBER(B7),B7-$B$3,"") | E7: =COUNTIF(Raspored!$E$5:$E$88,"x")
A8: Papir i karton | B8: =IFERROR(1/(1/_xlfn.MINIFS(Raspored!$A$5:$A$88,Raspored!$F$5:$F$88,"x",Raspored!$A$5:$A$88,">="&$B$3)),"nema više u 2026.") | C8: =IF(ISNUMBER(B8),INDEX({"nedjelja","ponedjeljak","utorak","srijeda","četvrtak","petak","subota"},WEEKDAY(B8)),"") | D8: =IF(ISNUMBER(B8),B8-$B$3,"") | E8: =COUNTIF(Raspored!$F$5:$F$88,"x")
A10: Broj odvoza po mjesecu
A11: Mjesec | B11: Miješani komunalni otpad | C11: Plastika i metal | D11: Papir i karton
A12: siječanj | B12: =COUNTIFS(Raspored!$C$5:$C$88,$A12,Raspored!$D$5:$D$88,"x") | C12: =COUNTIFS(Raspored!$C$5:$C$88,$A12,Raspored!$E$5:$E$88,"x") | D12: =COUNTIFS(Raspored!$C$5:$C$88,$A12,Raspored!$F$5:$F$88,"x")
A13: veljača | B13: =COUNTIFS(Raspored!$C$5:$C$88,$A13,Raspored!$D$5:$D$88,"x") | C13: =COUNTIFS(Raspored!$C$5:$C$88,$A13,Raspored!$E$5:$E$88,"x") | D13: =COUNTIFS(Raspored!$C$5:$C$88,$A13,Raspored!$F$5:$F$88,"x")
A14: ožujak | B14: =COUNTIFS(Raspored!$C$5:$C$88,$A14,Raspored!$D$5:$D$88,"x") | C14: =COUNTIFS(Raspored!$C$5:$C$88,$A14,Raspored!$E$5:$E$88,"x") | D14: =COUNTIFS(Raspored!$C$5:$C$88,$A14,Raspored!$F$5:$F$88,"x")
A15: travanj | B15: =COUNTIFS(Raspored!$C$5:$C$88,$A15,Raspored!$D$5:$D$88,"x") | C15: =COUNTIFS(Raspored!$C$5:$C$88,$A15,Raspored!$E$5:$E$88,"x") | D15: =COUNTIFS(Raspored!$C$5:$C$88,$A15,Raspored!$F$5:$F$88,"x")
A16: svibanj | B16: =COUNTIFS(Raspored!$C$5:$C$88,$A16,Raspored!$D$5:$D$88,"x") | C16: =COUNTIFS(Raspored!$C$5:$C$88,$A16,Raspored!$E$5:$E$88,"x") | D16: =COUNTIFS(Raspored!$C$5:$C$88,$A16,Raspored!$F$5:$F$88,"x")
A17: lipanj | B17: =COUNTIFS(Raspored!$C$5:$C$88,$A17,Raspored!$D$5:$D$88,"x") | C17: =COUNTIFS(Raspored!$C$5:$C$88,$A17,Raspored!$E$5:$E$88,"x") | D17: =COUNTIFS(Raspored!$C$5:$C$88,$A17,Raspored!$F$5:$F$88,"x")
A18: srpanj | B18: =COUNTIFS(Raspored!$C$5:$C$88,$A18,Raspored!$D$5:$D$88,"x") | C18: =COUNTIFS(Raspored!$C$5:$C$88,$A18,Raspored!$E$5:$E$88,"x") | D18: =COUNTIFS(Raspored!$C$5:$C$88,$A18,Raspored!$F$5:$F$88,"x")
A19: kolovoz | B19: =COUNTIFS(Raspored!$C$5:$C$88,$A19,Raspored!$D$5:$D$88,"x") | C19: =COUNTIFS(Raspored!$C$5:$C$88,$A19,Raspored!$E$5:$E$88,"x") | D19: =COUNTIFS(Raspored!$C$5:$C$88,$A19,Raspored!$F$5:$F$88,"x")
A20: rujan | B20: =COUNTIFS(Raspored!$C$5:$C$88,$A20,Raspored!$D$5:$D$88,"x") | C20: =COUNTIFS(Raspored!$C$5:$C$88,$A20,Raspored!$E$5:$E$88,"x") | D20: =COUNTIFS(Raspored!$C$5:$C$88,$A20,Raspored!$F$5:$F$88,"x")
A21: listopad | B21: =COUNTIFS(Raspored!$C$5:$C$88,$A21,Raspored!$D$5:$D$88,"x") | C21: =COUNTIFS(Raspored!$C$5:$C$88,$A21,Raspored!$E$5:$E$88,"x") | D21: =COUNTIFS(Raspored!$C$5:$C$88,$A21,Raspored!$F$5:$F$88,"x")
A22: studeni | B22: =COUNTIFS(Raspored!$C$5:$C$88,$A22,Raspored!$D$5:$D$88,"x") | C22: =COUNTIFS(Raspored!$C$5:$C$88,$A22,Raspored!$E$5:$E$88,"x") | D22: =COUNTIFS(Raspored!$C$5:$C$88,$A22,Raspored!$F$5:$F$88,"x")
A23: prosinac | B23: =COUNTIFS(Raspored!$C$5:$C$88,$A23,Raspored!$D$5:$D$88,"x") | C23: =COUNTIFS(Raspored!$C$5:$C$88,$A23,Raspored!$E$5:$E$88,"x") | D23: =COUNTIFS(Raspored!$C$5:$C$88,$A23,Raspored!$F$5:$F$88,"x")
A24: Ukupno | B24: =SUM(B12:B23) | C24: =SUM(C12:C23) | D24: =SUM(D12:D23)
A26: Napomene:
A27: • Crveno označeni datumi u listu "Raspored" su pomaknuti zbog neradnog dana u tom tjednu (inače je odvoz petkom).
A28: • PDF ne navodi naselja po terenima; svoj teren (dan odvoza miješanog otpada: četvrtak, petak) provjerite kod Mull-Transa (049/587-837, info@mull-trans.hr). Glomazni otpad (raspon dana; dan za pojedino naselje nije objavljen): 9.–13.3.; 8.–12.6.; 7.–11.9.; 7.–11.12. U službenoj evidenciji davatelja usluge (stanje 5.10.2026.) za ovu općinu naveden je Michieli-Tomić d.o.o.; Mull-Trans ipak objavljuje raspored za 2026. Izvor: https://mull-trans.hr/wp-content/uploads/2026/07/Opcina-Stankovci-raspored-za-2026.-izmjene-i-dopune.pdf (PDF izmijenjen 30.07.2026.)
A29: • Biootpad se na ovom području ne odvozi; preporučuje se kućno kompostiranje.
A30: • Rasporede za općine koje je ranije opsluživao Eko-Flor Plus d.o.o. sada objavljuje Mull-Trans d.o.o. na mull-trans.hr (izbornik Područje); neki PDF-ovi i dalje nose oznaku i kontakte Eko-Flora.
A31: • Spremnike treba iznijeti najkasnije do 6:00 na dan odvoza, na vidljivo mjesto pored obračunskog mjesta.
A32: • Glomazni otpad odvozi se na zahtjev podnesen najkasnije 3 radna dana prije termina: 049/587-837, glomazni@mull-trans.hr (stariji PDF-ovi navode glomazni@eko-flor.hr).
A33: • Blagdani: pomaci su ucrtani u kalendare (sivo ili uokvireno označen blagdan, strelica do zamjenskog dana, najčešće subote); takvi datumi označeni su kao pomaknuti.
A34: • Mobilno reciklažno dvorište (MRD) nije odvoz s kućnog praga; datumi su u napomeni zone, lokacije i vrijeme u PDF-u općine.
A35: • Nije uključeno: Štefanje (na mull-trans.hr je samo stariji raspored, Opcina-Stefanje-2025.pdf).

Sheet Raspored
A1: Raspored odvoza otpada 2026., Zona 57 (Stankovci)
A2: "x" = odvoz tog dana. Spremnike iznijeti do 07:00. Prošli datumi su posivljeni.
A4: Datum | B4: Dan | C4: Mjesec | D4: Miješani komunalni otpad | E4: Plastika i metal | F4: Papir i karton | G4: Napomena
A5: 46024 | B5: petak | C5: siječanj | D5: x
A6: 46031 | B6: petak | C6: siječanj | D6: x
A7: 46038 | B7: petak | C7: siječanj | D7: x
A8: 46043 | B8: srijeda | C8: siječanj | E8: x
A9: 46045 | B9: petak | C9: siječanj | D9: x
A10: 46050 | B10: srijeda | C10: siječanj | F10: x
A11: 46052 | B11: petak | C11: siječanj | D11: x
A12: 46059 | B12: petak | C12: veljača | D12: x
A13: 46066 | B13: petak | C13: veljača | D13: x
A14: 46071 | B14: srijeda | C14: veljača | E14: x
A15: 46073 | B15: petak | C15: veljača | D15: x
A16: 46078 | B16: srijeda | C16: veljača | F16: x
A17: 46080 | B17: petak | C17: veljača | D17: x
A18: 46087 | B18: petak | C18: ožujak | D18: x
A19: 46094 | B19: petak | C19: ožujak | D19: x
A20: 46099 | B20: srijeda | C20: ožujak | E20: x
A21: 46101 | B21: petak | C21: ožujak | D21: x
A22: 46106 | B22: srijeda | C22: ožujak | F22: x
A23: 46108 | B23: petak | C23: ožujak | D23: x
A24: 46115 | B24: petak | C24: travanj | D24: x
A25: 46122 | B25: petak | C25: travanj | D25: x
A26: 46129 | B26: petak | C26: travanj | D26: x
A27: 46134 | B27: srijeda | C27: travanj | E27: x
A28: 46136 | B28: petak | C28: travanj | D28: x
A29: 46140 | B29: utorak | C29: travanj | F29: x
A30: 46141 | B30: srijeda | C30: travanj | D30: x | G30: Pomaknuto zbog neradnog dana u tjednu
A31: 46150 | B31: petak | C31: svibanj | D31: x
A32: 46157 | B32: petak | C32: svibanj | D32: x
A33: 46162 | B33: srijeda | C33: svibanj | E33: x
A34: 46164 | B34: petak | C34: svibanj | D34: x
A35: 46169 | B35: srijeda | C35: svibanj | F35: x
A36: 46171 | B36: petak | C36: svibanj | D36: x
A37: 46178 | B37: petak | C37: lipanj | D37: x
A38: 46185 | B38: petak | C38: lipanj | D38: x
A39: 46190 | B39: srijeda | C39: lipanj | E39: x
A40: 46192 | B40: petak | C40: lipanj | D40: x
A41: 46197 | B41: srijeda | C41: lipanj | F41: x
...

Sheet Po vrsti
A1: Datum | B1: Dan | C1: Vrsta otpada | D1: Napomena
A2: 46024 | B2: petak | C2: Miješani komunalni otpad
A3: 46031 | B3: petak | C3: Miješani komunalni otpad
A4: 46038 | B4: petak | C4: Miješani komunalni otpad
A5: 46043 | B5: srijeda | C5: Plastika i metal
A6: 46045 | B6: petak | C6: Miješani komunalni otpad
A7: 46050 | B7: srijeda | C7: Papir i karton
A8: 46052 | B8: petak | C8: Miješani komunalni otpad
A9: 46059 | B9: petak | C9: Miješani komunalni otpad
A10: 46066 | B10: petak | C10: Miješani komunalni otpad
A11: 46071 | B11: srijeda | C11: Plastika i metal
A12: 46073 | B12: petak | C12: Miješani komunalni otpad
A13: 46078 | B13: srijeda | C13: Papir i karton
... A26: 46140 | B26: utorak | C26: Papir i karton
A27: 46141 | B27: srijeda | C27: Miješani komunalni otpad | D27: Pomaknuto zbog neradnog dana u tjednu
A28: 46150 | B28: petak | C28: Miješani komunalni otpad
A29: 46157 | B29: petak | C29: Miješani komunalni otpad
A30: 46162 | B30: srijeda | C30: Plastika i metal
A31: 46164 | B31: petak | C31: Miješani komunalni otpad
A32: 46169 | B32: srijeda | C32: Papir i karton
A33: 46171 | B33: petak | C33: Miješani komunalni otpad
A34: 46178 | B34: petak | C34: Miješani komunalni otpad
A35: 46185 | B35: petak | C35: Miješani komunalni otpad
A36: 46190 | B36: srijeda | C36: Plastika i metal
A37: 46192 | B37: petak | C37: Miješani komunalni otpad
A38: 46197 | B38: srijeda | C38: Papir i karton
A39: 46199 | B39: petak | C39: Miješani komunalni otpad
... A83: 46378 | B83: utorak | C83: Plastika i metal
A84: 46379 | B84: srijeda | C84: Miješani komunalni otpad | D84: Pomaknuto zbog neradnog dana u tjednu
A85: 46385 | B85: utorak | C85: Papir i karton
