Workbook

Sheet Pregled
A1: Zona 19, 2026: pregled odvoza
A3: Danas | B3: =TODAY()
A5: Vrsta otpada | B5: Sljedeći odvoz | C5: Dan | D5: Za dana | E5: Ukupno u 2026.
A6: Miješani komunalni otpad | B6: =IFERROR(1/(1/_xlfn.MINIFS(Raspored!$A$5:$A$44,Raspored!$D$5:$D$44,"x",Raspored!$A$5:$A$44,">="&$B$3)),"nema više u 2026.") | C6: =IF(ISNUMBER(B6),INDEX({"nedjelja","ponedjeljak","utorak","srijeda","četvrtak","petak","subota"},WEEKDAY(B6)),"") | D6: =IF(ISNUMBER(B6),B6-$B$3,"") | E6: =COUNTIF(Raspored!$D$5:$D$44,"x")
A7: Biootpad | B7: =IFERROR(1/(1/_xlfn.MINIFS(Raspored!$A$5:$A$44,Raspored!$E$5:$E$44,"x",Raspored!$A$5:$A$44,">="&$B$3)),"nema više u 2026.") | C7: =IF(ISNUMBER(B7),INDEX({"nedjelja","ponedjeljak","utorak","srijeda","četvrtak","petak","subota"},WEEKDAY(B7)),"") | D7: =IF(ISNUMBER(B7),B7-$B$3,"") | E7: =COUNTIF(Raspored!$E$5:$E$44,"x")
A8: Plastika | B8: =IFERROR(1/(1/_xlfn.MINIFS(Raspored!$A$5:$A$44,Raspored!$F$5:$F$44,"x",Raspored!$A$5:$A$44,">="&$B$3)),"nema više u 2026.") | C8: =IF(ISNUMBER(B8),INDEX({"nedjelja","ponedjeljak","utorak","srijeda","četvrtak","petak","subota"},WEEKDAY(B8)),"") | D8: =IF(ISNUMBER(B8),B8-$B$3,"") | E8: =COUNTIF(Raspored!$F$5:$F$44,"x")
A9: Papir i karton | B9: =IFERROR(1/(1/_xlfn.MINIFS(Raspored!$A$5:$A$44,Raspored!$G$5:$G$44,"x",Raspored!$A$5:$A$44,">="&$B$3)),"nema više u 2026.") | C9: =IF(ISNUMBER(B9),INDEX({"nedjelja","ponedjeljak","utorak","srijeda","četvrtak","petak","subota"},WEEKDAY(B9)),"") | D9: =IF(ISNUMBER(B9),B9-$B$3,"") | E9: =COUNTIF(Raspored!$G$5:$G$44,"x")
A10: Staklo | B10: =IFERROR(1/(1/_xlfn.MINIFS(Raspored!$A$5:$A$44,Raspored!$H$5:$H$44,"x",Raspored!$A$5:$A$44,">="&$B$3)),"nema više u 2026.") | C10: =IF(ISNUMBER(B10),INDEX({"nedjelja","ponedjeljak","utorak","srijeda","četvrtak","petak","subota"},WEEKDAY(B10)),"") | D10: =IF(ISNUMBER(B10),B10-$B$3,"") | E10: =COUNTIF(Raspored!$H$5:$H$44,"x")
A11: Metal | B11: =IFERROR(1/(1/_xlfn.MINIFS(Raspored!$A$5:$A$44,Raspored!$I$5:$I$44,"x",Raspored!$A$5:$A$44,">="&$B$3)),"nema više u 2026.") | C11: =IF(ISNUMBER(B11),INDEX({"nedjelja","ponedjeljak","utorak","srijeda","četvrtak","petak","subota"},WEEKDAY(B11)),"") | D11: =IF(ISNUMBER(B11),B11-$B$3,"") | E11: =COUNTIF(Raspored!$I$5:$I$44,"x")
A13: Broj odvoza po mjesecu
A14: Mjesec | B14: Miješani komunalni otpad | C14: Biootpad | D14: Plastika | E14: Papir i karton | F14: Staklo | G14: Metal
A15: siječanj | B15: =COUNTIFS(Raspored!$C$5:$C$44,$A15,Raspored!$D$5:$D$44,"x") | C15: =COUNTIFS(Raspored!$C$5:$C$44,$A15,Raspored!$E$5:$E$44,"x") | D15: =COUNTIFS(Raspored!$C$5:$C$44,$A15,Raspored!$F$5:$F$44,"x") | E15: =COUNTIFS(Raspored!$C$5:$C$44,$A15,Raspored!$G$5:$G$44,"x") | F15: =COUNTIFS(Raspored!$C$5:$C$44,$A15,Raspored!$H$5:$H$44,"x") | G15: =COUNTIFS(Raspored!$C$5:$C$44,$A15,Raspored!$I$5:$I$44,"x")
A16: veljača | B16: =COUNTIFS(Raspored!$C$5:$C$44,$A16,Raspored!$D$5:$D$44,"x") | C16: =COUNTIFS(Raspored!$C$5:$C$44,$A16,Raspored!$E$5:$E$44,"x") | D16: =COUNTIFS(Raspored!$C$5:$C$44,$A16,Raspored!$F$5:$F$44,"x") | E16: =COUNTIFS(Raspored!$C$5:$C$44,$A16,Raspored!$G$5:$G$44,"x") | F16: =COUNTIFS(Raspored!$C$5:$C$44,$A16,Raspored!$H$5:$H$44,"x") | G16: =COUNTIFS(Raspored!$C$5:$C$44,$A16,Raspored!$I$5:$I$44,"x")
A17: ožujak | B17: =COUNTIFS(Raspored!$C$5:$C$44,$A17,Raspored!$D$5:$D$44,"x") | C17: =COUNTIFS(Raspored!$C$5:$C$44,$A17,Raspored!$E$5:$E$44,"x") | D17: =COUNTIFS(Raspored!$C$5:$C$44,$A17,Raspored!$F$5:$F$44,"x") | E17: =COUNTIFS(Raspored!$C$5:$C$44,$A17,Raspored!$G$5:$G$44,"x") | F17: =COUNTIFS(Raspored!$C$5:$C$44,$A17,Raspored!$H$5:$H$44,"x") | G17: =COUNTIFS(Raspored!$C$5:$C$44,$A17,Raspored!$I$5:$I$44,"x")
A18: travanj | B18: =COUNTIFS(Raspored!$C$5:$C$44,$A18,Raspored!$D$5:$D$44,"x") | C18: =COUNTIFS(Raspored!$C$5:$C$44,$A18,Raspored!$E$5:$E$44,"x") | D18: =COUNTIFS(Raspored!$C$5:$C$44,$A18,Raspored!$F$5:$F$44,"x") | E18: =COUNTIFS(Raspored!$C$5:$C$44,$A18,Raspored!$G$5:$G$44,"x") | F18: =COUNTIFS(Raspored!$C$5:$C$44,$A18,Raspored!$H$5:$H$44,"x") | G18: =COUNTIFS(Raspored!$C$5:$C$44,$A18,Raspored!$I$5:$I$44,"x")
A19: svibanj | B19: =COUNTIFS(Raspored!$C$5:$C$44,$A19,Raspored!$D$5:$D$44,"x") | C19: =COUNTIFS(Raspored!$C$5:$C$44,$A19,Raspored!$E$5:$E$44,"x") | D19: =COUNTIFS(Raspored!$C$5:$C$44,$A19,Raspored!$F$5:$F$44,"x") | E19: =COUNTIFS(Raspored!$C$5:$C$44,$A19,Raspored!$G$5:$G$44,"x") | F19: =COUNTIFS(Raspored!$C$5:$C$44,$A19,Raspored!$H$5:$H$44,"x") | G19: =COUNTIFS(Raspored!$C$5:$C$44,$A19,Raspored!$I$5:$I$44,"x")
A20: lipanj | B20: =COUNTIFS(Raspored!$C$5:$C$44,$A20,Raspored!$D$5:$D$44,"x") | C20: =COUNTIFS(Raspored!$C$5:$C$44,$A20,Raspored!$E$5:$E$44,"x") | D20: =COUNTIFS(Raspored!$C$5:$C$44,$A20,Raspored!$F$5:$F$44,"x") | E20: =COUNTIFS(Raspored!$C$5:$C$44,$A20,Raspored!$G$5:$G$44,"x") | F20: =COUNTIFS(Raspored!$C$5:$C$44,$A20,Raspored!$H$5:$H$44,"x") | G20: =COUNTIFS(Raspored!$C$5:$C$44,$A20,Raspored!$I$5:$I$44,"x")
A21: srpanj | B21: =COUNTIFS(Raspored!$C$5:$C$44,$A21,Raspored!$D$5:$D$44,"x") | C21: =COUNTIFS(Raspored!$C$5:$C$44,$A21,Raspored!$E$5:$E$44,"x") | D21: =COUNTIFS(Raspored!$C$5:$C$44,$A21,Raspored!$F$5:$F$44,"x") | E21: =COUNTIFS(Raspored!$C$5:$C$44,$A21,Raspored!$G$5:$G$44,"x") | F21: =COUNTIFS(Raspored!$C$5:$C$44,$A21,Raspored!$H$5:$H$44,"x") | G21: =COUNTIFS(Raspored!$C$5:$C$44,$A21,Raspored!$I$5:$I$44,"x")
A22: kolovoz | B22: =COUNTIFS(Raspored!$C$5:$C$44,$A22,Raspored!$D$5:$D$44,"x") | C22: =COUNTIFS(Raspored!$C$5:$C$44,$A22,Raspored!$E$5:$E$44,"x") | D22: =COUNTIFS(Raspored!$C$5:$C$44,$A22,Raspored!$F$5:$F$44,"x") | E22: =COUNTIFS(Raspored!$C$5:$C$44,$A22,Raspored!$G$5:$G$44,"x") | F22: =COUNTIFS(Raspored!$C$5:$C$44,$A22,Raspored!$H$5:$H$44,"x") | G22: =COUNTIFS(Raspored!$C$5:$C$44,$A22,Raspored!$I$5:$I$44,"x")
A23: rujan | B23: =COUNTIFS(Raspored!$C$5:$C$44,$A23,Raspored!$D$5:$D$44,"x") | C23: =COUNTIFS(Raspored!$C$5:$C$44,$A23,Raspored!$E$5:$E$44,"x") | D23: =COUNTIFS(Raspored!$C$5:$C$44,$A23,Raspored!$F$5:$F$44,"x") | E23: =COUNTIFS(Raspored!$C$5:$C$44,$A23,Raspored!$G$5:$G$44,"x") | F23: =COUNTIFS(Raspored!$C$5:$C$44,$A23,Raspored!$H$5:$H$44,"x") | G23: =COUNTIFS(Raspored!$C$5:$C$44,$A23,Raspored!$I$5:$I$44,"x")
A24: listopad | B24: =COUNTIFS(Raspored!$C$5:$C$44,$A24,Raspored!$D$5:$D$44,"x") | C24: =COUNTIFS(Raspored!$C$5:$C$44,$A24,Raspored!$E$5:$E$44,"x") | D24: =COUNTIFS(Raspored!$C$5:$C$44,$A24,Raspored!$F$5:$F$44,"x") | E24: =COUNTIFS(Raspored!$C$5:$C$44,$A24,Raspored!$G$5:$G$44,"x") | F24: =COUNTIFS(Raspored!$C$5:$C$44,$A24,Raspored!$H$5:$H$44,"x") | G24: =COUNTIFS(Raspored!$C$5:$C$44,$A24,Raspored!$I$5:$I$44,"x")
A25: studeni | B25: =COUNTIFS(Raspored!$C$5:$C$44,$A25,Raspored!$D$5:$D$44,"x") | C25: =COUNTIFS(Raspored!$C$5:$C$44,$A25,Raspored!$E$5:$E$44,"x") | D25: =COUNTIFS(Raspored!$C$5:$C$44,$A25,Raspored!$F$5:$F$44,"x") | E25: =COUNTIFS(Raspored!$C$5:$C$44,$A25,Raspored!$G$5:$G$44,"x") | F25: =COUNTIFS(Raspored!$C$5:$C$44,$A25,Raspored!$H$5:$H$44,"x") | G25: =COUNTIFS(Raspored!$C$5:$C$44,$A25,Raspored!$I$5:$I$44,"x")
A26: prosinac | B26: =COUNTIFS(Raspored!$C$5:$C$44,$A26,Raspored!$D$5:$D$44,"x") | C26: =COUNTIFS(Raspored!$C$5:$C$44,$A26,Raspored!$E$5:$E$44,"x") | D26: =COUNTIFS(Raspored!$C$5:$C$44,$A26,Raspored!$F$5:$F$44,"x") | E26: =COUNTIFS(Raspored!$C$5:$C$44,$A26,Raspored!$G$5:$G$44,"x") | F26: =COUNTIFS(Raspored!$C$5:$C$44,$A26,Raspored!$H$5:$H$44,"x") | G26: =COUNTIFS(Raspored!$C$5:$C$44,$A26,Raspored!$I$5:$I$44,"x")
A27: Ukupno | B27: =SUM(B15:B26) | C27: =SUM(C15:C26) | D27: =SUM(D15:D26) | E27: =SUM(E15:E26) | F27: =SUM(F15:F26) | G27: =SUM(G15:G26)
A29: Napomene:
A30: • Spremnike iznijeti do 06:00 na dan odvoza.
A31: • Raspored vrijedi za kućanstva s pojedinačnim spremnicima (skupina A); zgrade sa zajedničkim spremnicima i poslovni korisnici mogu imati drugačiji raspored na moja.cistoca-vz.hr.
A32: • Reciklažna dvorišta Varaždin 1 i 2, Motičnjak 9 i 9/A, Varaždin.
A33: • Pelene (ljubičasti spremnik) za korisnike koji su ih prijavili odvoze se istim danom kad i miješani otpad.

Sheet Raspored
A1: Raspored odvoza otpada 2026., Zona 19 (Varaždin)
A2: "x" = odvoz tog dana. Spremnike iznijeti do 07:00. Prošli datumi su posivljeni.
A4: Datum | B4: Dan | C4: Mjesec | D4: Miješani komunalni otpad | E4: Biootpad | F4: Plastika | G4: Papir i karton | H4: Staklo | I4: Metal | J4: Napomena
A5: 46034 | B5: ponedjeljak | C5: siječanj | D5: x | E5: x | F5: x | G5: x
A6: 46048 | B6: ponedjeljak | C6: siječanj | D6: x | E6: x | F6: x | G6: x
A7: 46062 | B7: ponedjeljak | C7: veljača | D7: x | E7: x | F7: x | G7: x
A8: 46076 | B8: ponedjeljak | C8: veljača | D8: x | E8: x | F8: x | G8: x | I8: x
A9: 46090 | B9: ponedjeljak | C9: ožujak | D9: x | E9: x | F9: x | G9: x
A10: 46104 | B10: ponedjeljak | C10: ožujak | D10: x | E10: x | F10: x | G10: x | H10: x
A11: 46118 | B11: ponedjeljak | C11: travanj | D11: x | E11: x | F11: x | G11: x
A12: 46132 | B12: ponedjeljak | C12: travanj | D12: x | E12: x | F12: x | G12: x
A13: 46146 | B13: ponedjeljak | C13: svibanj | D13: x | E13: x | F13: x | G13: x
A14: 46153 | B14: ponedjeljak | C14: svibanj | E14: x
A15: 46160 | B15: ponedjeljak | C15: svibanj | D15: x | E15: x | F15: x | G15: x
A16: 46167 | B16: ponedjeljak | C16: svibanj | E16: x | I16: x
A17: 46174 | B17: ponedjeljak | C17: lipanj | D17: x | E17: x | F17: x | G17: x
A18: 46181 | B18: ponedjeljak | C18: lipanj | E18: x
A19: 46188 | B19: ponedjeljak | C19: lipanj | D19: x | E19: x | F19: x | G19: x
A20: 46195 | B20: ponedjeljak | C20: lipanj | E20: x
A21: 46202 | B21: ponedjeljak | C21: lipanj | D21: x | E21: x | F21: x | G21: x | H21: x
A22: 46209 | B22: ponedjeljak | C22: srpanj | E22: x
A23: 46216 | B23: ponedjeljak | C23: srpanj | D23: x | E23: x | F23: x | G23: x
A24: 46223 | B24: ponedjeljak | C24: srpanj | E24: x
A25: 46230 | B25: ponedjeljak | C25: srpanj | D25: x | E25: x | F25: x | G25: x | I25: x
A26: 46237 | B26: ponedjeljak | C26: kolovoz | E26: x
A27: 46244 | B27: ponedjeljak | C27: kolovoz | D27: x | E27: x | F27: x | G27: x
A28: 46251 | B28: ponedjeljak | C28: kolovoz | E28: x
A29: 46258 | B29: ponedjeljak | C29: kolovoz | D29: x | E29: x | F29: x | G29: x | H29: x
A30: 46265 | B30: ponedjeljak | C30: kolovoz | E30: x
A31: 46272 | B31: ponedjeljak | C31: rujan | D31: x | E31: x | F31: x | G31: x
A32: 46279 | B32: ponedjeljak | C32: rujan | E32: x
A33: 46286 | B33: ponedjeljak | C33: rujan | D33: x | E33: x | F33: x | G33: x
A34: 46293 | B34: ponedjeljak | C34: rujan | E34: x
A35: 46300 | B35: ponedjeljak | C35: listopad | D35: x | E35: x | F35: x | G35: x
A36: 46307 | B36: ponedjeljak | C36: listopad | E36: x
A37: 46314 | B37: ponedjeljak | C37: listopad | D37: x | E37: x | F37: x | G37: x
A38: 46321 | B38: ponedjeljak | C38: listopad | E38: x | I38: x
A39: 46328 | B39: ponedjeljak | C39: studeni | D39: x | E39: x | F39: x | G39: x
A40: 46342 | B40: ponedjeljak | C40: studeni | D40: x | E40: x | F40: x | G40: x
A41: 46349 | B41: ponedjeljak | C41: studeni | H41: x
...

Sheet Po vrsti
A1: Datum | B1: Dan | C1: Vrsta otpada | D1: Napomena
A2: 46034 | B2: ponedjeljak | C2: Miješani komunalni otpad
A3: 46034 | B3: ponedjeljak | C3: Biootpad
A4: 46034 | B4: ponedjeljak | C4: Plastika
A5: 46034 | B5: ponedjeljak | C5: Papir i karton
A6: 46048 | B6: ponedjeljak | C6: Miješani komunalni otpad
A7: 46048 | B7: ponedjeljak | C7: Biootpad
A8: 46048 | B8: ponedjeljak | C8: Plastika
A9: 46048 | B9: ponedjeljak | C9: Papir i karton
A10: 46062 | B10: ponedjeljak | C10: Miješani komunalni otpad
A11: 46062 | B11: ponedjeljak | C11: Biootpad
A12: 46062 | B12: ponedjeljak | C12: Plastika
A13: 46062 | B13: ponedjeljak | C13: Papir i karton
... A126: 46384 | B126: ponedjeljak | C126: Papir i karton

Sheet Ulice i naselja
A1: Zona 19 (Varaždin): ulice i naselja
A4: Ulica / naselje
A5: Gorčica (Gojanec)
A6: Kalnička cesta (Jalkovec)
A7: Nova ulica (Jalkovec)
A8: Plitvička ulica (Gojanec)
A9: Plitvička ulica (Jalkovec)
A10: Trg Ljudevita Gaja (Jalkovec)
A11: Ulica Ante Kovačića (Poljana Biškupečka)
A12: Ulica Augusta Šenoe (Poljana Biškupečka)
A13: Ulica Florijana Bobića (Jalkovec)
A14: Ulica Ljudevita Gaja (Gojanec)
... A36: Čretna ulica (Jalkovec)
